<?xml version="1.0" ?>
<robot name="deep_ballbot" xmlns:xacro="http://www.ros.org/wiki/xacro">

<xacro:include filename="$(find deep_ballbot_description)/urdf/materials.xacro" />
<xacro:include filename="$(find deep_ballbot_description)/urdf/deep_ballbot.trans" />
<xacro:include filename="$(find deep_ballbot_description)/urdf/deep_ballbot.gazebo" />
<link name="base_link">
  <inertial>
    <origin rpy="0 0 0" xyz="1.044895162337113e-16 -4.0782779191072703e-16 0.2890000000000001"/>
    <mass value="0.1429407"/>
    <inertia ixx="0.001077" ixy="-0.0" ixz="0.0" iyy="0.001077" iyz="0.0" izz="1.1e-05"/>
  </inertial>
  <visual>
    <origin rpy="0 0 0" xyz="0 0 0"/>
    <geometry>
      <mesh filename="package://deep_ballbot_description/meshes/base_link.stl" scale="0.001 0.001 0.001"/>
    </geometry>
    <material name="silver"/>
  </visual>
  <collision>
    <origin rpy="0 0 0" xyz="0 0 0"/>
    <geometry>
      <mesh filename="package://deep_ballbot_description/meshes/base_link.stl" scale="0.001 0.001 0.001"/>
    </geometry>
  </collision>
</link>

<link name="base_shell1_1">
  <inertial>
    <origin rpy="0 0 0" xyz="-0.03154930294610876 0.01821499854868268 0.021364464404157207"/>
    <mass value="0.03897424370875784"/>
    <inertia ixx="3.3e-05" ixy="-1.1e-05" ixz="6e-06" iyy="2e-05" iyz="-3e-06" izz="3.8e-05"/>
  </inertial>
  <visual>
    <origin rpy="0 0 0" xyz="-0.0 -0.0 -0.139"/>
    <geometry>
      <mesh filename="package://deep_ballbot_description/meshes/base_shell1_1.stl" scale="0.001 0.001 0.001"/>
    </geometry>
    <material name="silver"/>
  </visual>
  <collision>
    <origin rpy="0 0 0" xyz="-0.0 -0.0 -0.139"/>
    <geometry>
      <mesh filename="package://deep_ballbot_description/meshes/base_shell1_1.stl" scale="0.001 0.001 0.001"/>
    </geometry>
  </collision>
</link>

<link name="base_shell2_1">
  <inertial>
    <origin rpy="0 0 0" xyz="-3.417367020505995e-15 -0.037022459667432825 0.022039444136548486"/>
    <mass value="0.037632056653399956"/>
    <inertia ixx="1.3e-05" ixy="-0.0" ixz="-0.0" iyy="3.8e-05" iyz="6e-06" izz="3.7e-05"/>
  </inertial>
  <visual>
    <origin rpy="0 0 0" xyz="-0.0 -0.0 -0.139"/>
    <geometry>
      <mesh filename="package://deep_ballbot_description/meshes/base_shell2_1.stl" scale="0.001 0.001 0.001"/>
    </geometry>
    <material name="silver"/>
  </visual>
  <collision>
    <origin rpy="0 0 0" xyz="-0.0 -0.0 -0.139"/>
    <geometry>
      <mesh filename="package://deep_ballbot_description/meshes/base_shell2_1.stl" scale="0.001 0.001 0.001"/>
    </geometry>
  </collision>
</link>

<link name="base_plate2_1">
  <inertial>
    <origin rpy="0 0 0" xyz="-0.008447575075313324 0.0259707939694059 0.0029137797806522425"/>
    <mass value="0.029331775102842923"/>
    <inertia ixx="1.5e-05" ixy="-6e-06" ixz="-0.0" iyy="9e-06" iyz="0.0" izz="2.4e-05"/>
  </inertial>
  <visual>
    <origin rpy="0 0 0" xyz="-0.040768 0.044631 -0.184"/>
    <geometry>
      <mesh filename="package://deep_ballbot_description/meshes/base_plate2_1.stl" scale="0.001 0.001 0.001"/>
    </geometry>
    <material name="silver"/>
  </visual>
  <collision>
    <origin rpy="0 0 0" xyz="-0.040768 0.044631 -0.184"/>
    <geometry>
      <mesh filename="package://deep_ballbot_description/meshes/base_plate2_1.stl" scale="0.001 0.001 0.001"/>
    </geometry>
  </collision>
</link>

<link name="base_plate2_1">
  <inertial>
    <origin rpy="0 0 0" xyz="-0.026715575075313323 -0.005670206030594099 0.0029137797806522425"/>
    <mass value="0.029331775102842923"/>
    <inertia ixx="1.5e-05" ixy="-6e-06" ixz="-0.0" iyy="9e-06" iyz="0.0" izz="2.4e-05"/>
  </inertial>
  <visual>
    <origin rpy="0 0 0" xyz="-0.059036 0.01299 -0.184"/>
    <geometry>
      <mesh filename="package://deep_ballbot_description/meshes/base_plate2_1.stl" scale="0.001 0.001 0.001"/>
    </geometry>
    <material name="silver"/>
  </visual>
  <collision>
    <origin rpy="0 0 0" xyz="-0.059036 0.01299 -0.184"/>
    <geometry>
      <mesh filename="package://deep_ballbot_description/meshes/base_plate2_1.stl" scale="0.001 0.001 0.001"/>
    </geometry>
  </collision>
</link>

<link name="base_plate3_1">
  <inertial>
    <origin rpy="0 0 0" xyz="-0.018267999999997092 -0.02030158793881661 0.002913779780652437"/>
    <mass value="0.029331775102842902"/>
    <inertia ixx="5e-06" ixy="-0.0" ixz="0.0" iyy="1.9e-05" iyz="-0.0" izz="2.4e-05"/>
  </inertial>
  <visual>
    <origin rpy="0 0 0" xyz="-0.018268 -0.057622 -0.184"/>
    <geometry>
      <mesh filename="package://deep_ballbot_description/meshes/base_plate3_1.stl" scale="0.001 0.001 0.001"/>
    </geometry>
    <material name="silver"/>
  </visual>
  <collision>
    <origin rpy="0 0 0" xyz="-0.018268 -0.057622 -0.184"/>
    <geometry>
      <mesh filename="package://deep_ballbot_description/meshes/base_plate3_1.stl" scale="0.001 0.001 0.001"/>
    </geometry>
  </collision>
</link>

<link name="base_plate3_1">
  <inertial>
    <origin rpy="0 0 0" xyz="0.018268000000002907 -0.02030158793881661 0.002913779780652437"/>
    <mass value="0.029331775102842902"/>
    <inertia ixx="5e-06" ixy="-0.0" ixz="0.0" iyy="1.9e-05" iyz="-0.0" izz="2.4e-05"/>
  </inertial>
  <visual>
    <origin rpy="0 0 0" xyz="0.018268 -0.057622 -0.184"/>
    <geometry>
      <mesh filename="package://deep_ballbot_description/meshes/base_plate3_1.stl" scale="0.001 0.001 0.001"/>
    </geometry>
    <material name="silver"/>
  </visual>
  <collision>
    <origin rpy="0 0 0" xyz="0.018268 -0.057622 -0.184"/>
    <geometry>
      <mesh filename="package://deep_ballbot_description/meshes/base_plate3_1.stl" scale="0.001 0.001 0.001"/>
    </geometry>
  </collision>
</link>

<link name="base_plate1_1">
  <inertial>
    <origin rpy="0 0 0" xyz="0.02671557507531075 -0.005670206030589256 0.0029137797806522425"/>
    <mass value="0.029331775102842895"/>
    <inertia ixx="1.5e-05" ixy="6e-06" ixz="0.0" iyy="9e-06" iyz="0.0" izz="2.4e-05"/>
  </inertial>
  <visual>
    <origin rpy="0 0 0" xyz="0.059036 0.01299 -0.184"/>
    <geometry>
      <mesh filename="package://deep_ballbot_description/meshes/base_plate1_1.stl" scale="0.001 0.001 0.001"/>
    </geometry>
    <material name="silver"/>
  </visual>
  <collision>
    <origin rpy="0 0 0" xyz="0.059036 0.01299 -0.184"/>
    <geometry>
      <mesh filename="package://deep_ballbot_description/meshes/base_plate1_1.stl" scale="0.001 0.001 0.001"/>
    </geometry>
  </collision>
</link>

<link name="base_plate1_1">
  <inertial>
    <origin rpy="0 0 0" xyz="0.00844757507531075 0.02597079396941074 0.0029137797806522425"/>
    <mass value="0.029331775102842895"/>
    <inertia ixx="1.5e-05" ixy="6e-06" ixz="0.0" iyy="9e-06" iyz="0.0" izz="2.4e-05"/>
  </inertial>
  <visual>
    <origin rpy="0 0 0" xyz="0.040768 0.044631 -0.184"/>
    <geometry>
      <mesh filename="package://deep_ballbot_description/meshes/base_plate1_1.stl" scale="0.001 0.001 0.001"/>
    </geometry>
    <material name="silver"/>
  </visual>
  <collision>
    <origin rpy="0 0 0" xyz="0.040768 0.044631 -0.184"/>
    <geometry>
      <mesh filename="package://deep_ballbot_description/meshes/base_plate1_1.stl" scale="0.001 0.001 0.001"/>
    </geometry>
  </collision>
</link>

<link name="vertical_bay1_1">
  <inertial>
    <origin rpy="0 0 0" xyz="-1.6167557852567183e-07 1.1086679559124679e-07 0.03426796949760952"/>
    <mass value="0.02673500652833671"/>
    <inertia ixx="1.7e-05" ixy="4e-06" ixz="0.0" iyy="1.3e-05" iyz="0.0" izz="8e-06"/>
  </inertial>
  <visual>
    <origin rpy="0 0 0" xyz="0.023921 0.013811 -0.187"/>
    <geometry>
      <mesh filename="package://deep_ballbot_description/meshes/vertical_bay1_1.stl" scale="0.001 0.001 0.001"/>
    </geometry>
    <material name="silver"/>
  </visual>
  <collision>
    <origin rpy="0 0 0" xyz="0.023921 0.013811 -0.187"/>
    <geometry>
      <mesh filename="package://deep_ballbot_description/meshes/vertical_bay1_1.stl" scale="0.001 0.001 0.001"/>
    </geometry>
  </collision>
</link>

<link name="vertical_bay3_1">
  <inertial>
    <origin rpy="0 0 0" xyz="4.8585964403268e-15 -2.2173493367805275e-07 0.03430752132988982"/>
    <mass value="0.026769047843990493"/>
    <inertia ixx="1.1e-05" ixy="-0.0" ixz="-0.0" iyy="2e-05" iyz="0.0" izz="8e-06"/>
  </inertial>
  <visual>
    <origin rpy="0 0 0" xyz="-0.0 -0.027622 -0.187"/>
    <geometry>
      <mesh filename="package://deep_ballbot_description/meshes/vertical_bay3_1.stl" scale="0.001 0.001 0.001"/>
    </geometry>
    <material name="silver"/>
  </visual>
  <collision>
    <origin rpy="0 0 0" xyz="-0.0 -0.027622 -0.187"/>
    <geometry>
      <mesh filename="package://deep_ballbot_description/meshes/vertical_bay3_1.stl" scale="0.001 0.001 0.001"/>
    </geometry>
  </collision>
</link>

<link name="vertical_bay2_1">
  <inertial>
    <origin rpy="0 0 0" xyz="1.6167524612489825e-07 1.108674625403816e-07 0.034307521329889706"/>
    <mass value="0.026769047843990496"/>
    <inertia ixx="1.8e-05" ixy="-4e-06" ixz="0.0" iyy="1.3e-05" iyz="-0.0" izz="8e-06"/>
  </inertial>
  <visual>
    <origin rpy="0 0 0" xyz="-0.023921 0.013811 -0.187"/>
    <geometry>
      <mesh filename="package://deep_ballbot_description/meshes/vertical_bay2_1.stl" scale="0.001 0.001 0.001"/>
    </geometry>
    <material name="silver"/>
  </visual>
  <collision>
    <origin rpy="0 0 0" xyz="-0.023921 0.013811 -0.187"/>
    <geometry>
      <mesh filename="package://deep_ballbot_description/meshes/vertical_bay2_1.stl" scale="0.001 0.001 0.001"/>
    </geometry>
  </collision>
</link>

<link name="arduino_mount2_1">
  <inertial>
    <origin rpy="0 0 0" xyz="0.0024394246518729297 -0.0006681248315038978 -2.1615661864288205e-05"/>
    <mass value="0.023201510107960607"/>
    <inertia ixx="1.3e-05" ixy="-5e-06" ixz="-0.0" iyy="8e-06" iyz="-0.0" izz="1.2e-05"/>
  </inertial>
  <visual>
    <origin rpy="0 0 0" xyz="-0.026519 0.015311 -0.2195"/>
    <geometry>
      <mesh filename="package://deep_ballbot_description/meshes/arduino_mount2_1.stl" scale="0.001 0.001 0.001"/>
    </geometry>
    <material name="silver"/>
  </visual>
  <collision>
    <origin rpy="0 0 0" xyz="-0.026519 0.015311 -0.2195"/>
    <geometry>
      <mesh filename="package://deep_ballbot_description/meshes/arduino_mount2_1.stl" scale="0.001 0.001 0.001"/>
    </geometry>
  </collision>
</link>

<link name="arduino2_1">
  <inertial>
    <origin rpy="0 0 0" xyz="0.021682625979238306 0.03176671812995284 0.008758533737850571"/>
    <mass value="0.07636193365547596"/>
    <inertia ixx="4.6e-05" ixy="-1.6e-05" ixz="1e-06" iyy="3.2e-05" iyz="1e-06" izz="3.5e-05"/>
  </inertial>
  <visual>
    <origin rpy="0 0 0" xyz="-0.01462 0.04592 -0.211"/>
    <geometry>
      <mesh filename="package://deep_ballbot_description/meshes/arduino2_1.stl" scale="0.001 0.001 0.001"/>
    </geometry>
    <material name="silver"/>
  </visual>
  <collision>
    <origin rpy="0 0 0" xyz="-0.01462 0.04592 -0.211"/>
    <geometry>
      <mesh filename="package://deep_ballbot_description/meshes/arduino2_1.stl" scale="0.001 0.001 0.001"/>
    </geometry>
  </collision>
</link>

<link name="arduino1_1">
  <inertial>
    <origin rpy="0 0 0" xyz="0.01666958536509317 -0.034661355386450377 0.00875853373784699"/>
    <mass value="0.0763619336554754"/>
    <inertia ixx="4.9e-05" ixy="1.4e-05" ixz="0.0" iyy="2.9e-05" iyz="-1e-06" izz="3.5e-05"/>
  </inertial>
  <visual>
    <origin rpy="0 0 0" xyz="0.047078 -0.010299 -0.211"/>
    <geometry>
      <mesh filename="package://deep_ballbot_description/meshes/arduino1_1.stl" scale="0.001 0.001 0.001"/>
    </geometry>
    <material name="silver"/>
  </visual>
  <collision>
    <origin rpy="0 0 0" xyz="0.047078 -0.010299 -0.211"/>
    <geometry>
      <mesh filename="package://deep_ballbot_description/meshes/arduino1_1.stl" scale="0.001 0.001 0.001"/>
    </geometry>
  </collision>
</link>

<link name="simplefocshield1_1">
  <inertial>
    <origin rpy="0 0 0" xyz="0.005231903421714465 -0.03786042712161111 0.01045466263105585"/>
    <mass value="0.08735557008432586"/>
    <inertia ixx="4.9e-05" ixy="1.3e-05" ixz="-0.0" iyy="3e-05" iyz="2e-06" izz="3.4e-05"/>
  </inertial>
  <visual>
    <origin rpy="0 0 0" xyz="0.048464 -0.009499 -0.2109"/>
    <geometry>
      <mesh filename="package://deep_ballbot_description/meshes/simplefocshield1_1.stl" scale="0.001 0.001 0.001"/>
    </geometry>
    <material name="silver"/>
  </visual>
  <collision>
    <origin rpy="0 0 0" xyz="0.048464 -0.009499 -0.2109"/>
    <geometry>
      <mesh filename="package://deep_ballbot_description/meshes/simplefocshield1_1.stl" scale="0.001 0.001 0.001"/>
    </geometry>
  </collision>
</link>

<link name="simplefocshield2_1">
  <inertial>
    <origin rpy="0 0 0" xyz="0.030171764736892828 0.02346061939302205 0.010454662862077163"/>
    <mass value="0.08735557070138866"/>
    <inertia ixx="4.6e-05" ixy="-1.4e-05" ixz="-2e-06" iyy="3.3e-05" iyz="-1e-06" izz="3.4e-05"/>
  </inertial>
  <visual>
    <origin rpy="0 0 0" xyz="-0.016006 0.04672 -0.2109"/>
    <geometry>
      <mesh filename="package://deep_ballbot_description/meshes/simplefocshield2_1.stl" scale="0.001 0.001 0.001"/>
    </geometry>
    <material name="silver"/>
  </visual>
  <collision>
    <origin rpy="0 0 0" xyz="-0.016006 0.04672 -0.2109"/>
    <geometry>
      <mesh filename="package://deep_ballbot_description/meshes/simplefocshield2_1.stl" scale="0.001 0.001 0.001"/>
    </geometry>
  </collision>
</link>

<link name="simplefocshield3_1">
  <inertial>
    <origin rpy="0 0 0" xyz="-0.029512331570683524 0.014398807513327852 0.00654533732721993"/>
    <mass value="0.087355572863096"/>
    <inertia ixx="2.4e-05" ixy="-2e-06" ixz="2e-06" iyy="5.5e-05" iyz="1e-06" izz="3.4e-05"/>
  </inertial>
  <visual>
    <origin rpy="0 0 0" xyz="-0.032458 -0.037222 -0.2111"/>
    <geometry>
      <mesh filename="package://deep_ballbot_description/meshes/simplefocshield3_1.stl" scale="0.001 0.001 0.001"/>
    </geometry>
    <material name="silver"/>
  </visual>
  <collision>
    <origin rpy="0 0 0" xyz="-0.032458 -0.037222 -0.2111"/>
    <geometry>
      <mesh filename="package://deep_ballbot_description/meshes/simplefocshield3_1.stl" scale="0.001 0.001 0.001"/>
    </geometry>
  </collision>
</link>

<link name="arduino3_1">
  <inertial>
    <origin rpy="0 0 0" xyz="0.03835221134391349 0.002893637256497078 -0.008758533737797253"/>
    <mass value="0.07636193365547513"/>
    <inertia ixx="2.2e-05" ixy="-2e-06" ixz="-1e-06" iyy="5.6e-05" iyz="-0.0" izz="3.5e-05"/>
  </inertial>
  <visual>
    <origin rpy="0 0 0" xyz="0.032458 -0.035622 -0.228"/>
    <geometry>
      <mesh filename="package://deep_ballbot_description/meshes/arduino3_1.stl" scale="0.001 0.001 0.001"/>
    </geometry>
    <material name="silver"/>
  </visual>
  <collision>
    <origin rpy="0 0 0" xyz="0.032458 -0.035622 -0.228"/>
    <geometry>
      <mesh filename="package://deep_ballbot_description/meshes/arduino3_1.stl" scale="0.001 0.001 0.001"/>
    </geometry>
  </collision>
</link>

<link name="arduino_mount3_1">
  <inertial>
    <origin rpy="0 0 0" xyz="0.0006408842916291989 0.0024462938179583733 2.161566186476005e-05"/>
    <mass value="0.023201510107976293"/>
    <inertia ixx="5e-06" ixy="-0.0" ixz="0.0" iyy="1.6e-05" iyz="-0.0" izz="1.2e-05"/>
  </inertial>
  <visual>
    <origin rpy="0 0 0" xyz="-0.0 -0.030622 -0.2195"/>
    <geometry>
      <mesh filename="package://deep_ballbot_description/meshes/arduino_mount3_1.stl" scale="0.001 0.001 0.001"/>
    </geometry>
    <material name="silver"/>
  </visual>
  <collision>
    <origin rpy="0 0 0" xyz="-0.0 -0.030622 -0.2195"/>
    <geometry>
      <mesh filename="package://deep_ballbot_description/meshes/arduino_mount3_1.stl" scale="0.001 0.001 0.001"/>
    </geometry>
  </collision>
</link>

<link name="top_plate_1">
  <inertial>
    <origin rpy="0 0 0" xyz="0.023920999358290018 0.013810999483771 0.0001394387833444921"/>
    <mass value="0.03865794031509113"/>
    <inertia ixx="2.6e-05" ixy="-0.0" ixz="-0.0" iyy="2.6e-05" iyz="-0.0" izz="5.2e-05"/>
  </inertial>
  <visual>
    <origin rpy="0 0 0" xyz="0.023921 0.013811 -0.255"/>
    <geometry>
      <mesh filename="package://deep_ballbot_description/meshes/top_plate_1.stl" scale="0.001 0.001 0.001"/>
    </geometry>
    <material name="silver"/>
  </visual>
  <collision>
    <origin rpy="0 0 0" xyz="0.023921 0.013811 -0.255"/>
    <geometry>
      <mesh filename="package://deep_ballbot_description/meshes/top_plate_1.stl" scale="0.001 0.001 0.001"/>
    </geometry>
  </collision>
</link>

<link name="breadboard_1">
  <inertial>
    <origin rpy="0 0 0" xyz="-3.678428880243834e-10 -0.01750000047097254 0.0009999999999999454"/>
    <mass value="0.016254000000000088"/>
    <inertia ixx="2e-06" ixy="-0.0" ixz="-0.0" iyy="3e-06" iyz="-0.0" izz="4e-06"/>
  </inertial>
  <visual>
    <origin rpy="0 0 0" xyz="0.0 0.0105 -0.261"/>
    <geometry>
      <mesh filename="package://deep_ballbot_description/meshes/breadboard_1.stl" scale="0.001 0.001 0.001"/>
    </geometry>
    <material name="silver"/>
  </visual>
  <collision>
    <origin rpy="0 0 0" xyz="0.0 0.0105 -0.261"/>
    <geometry>
      <mesh filename="package://deep_ballbot_description/meshes/breadboard_1.stl" scale="0.001 0.001 0.001"/>
    </geometry>
  </collision>
</link>

<link name="arduino_nano_1">
  <inertial>
    <origin rpy="0 0 0" xyz="-0.001592270338889752 -0.000592000480611754 0.014355883406889203"/>
    <mass value="0.014605507737955568"/>
    <inertia ixx="1e-06" ixy="-0.0" ixz="0.0" iyy="2e-06" iyz="0.0" izz="3e-06"/>
  </inertial>
  <visual>
    <origin rpy="0 0 0" xyz="-0.000352 0.027408 -0.255"/>
    <geometry>
      <mesh filename="package://deep_ballbot_description/meshes/arduino_nano_1.stl" scale="0.001 0.001 0.001"/>
    </geometry>
    <material name="silver"/>
  </visual>
  <collision>
    <origin rpy="0 0 0" xyz="-0.000352 0.027408 -0.255"/>
    <geometry>
      <mesh filename="package://deep_ballbot_description/meshes/arduino_nano_1.stl" scale="0.001 0.001 0.001"/>
    </geometry>
  </collision>
</link>

<link name="rasbperry_pi_1">
  <inertial>
    <origin rpy="0 0 0" xyz="-0.0007540083650862473 0.013888830680914847 0.0229654725197333"/>
    <mass value="0.13472167579144456"/>
    <inertia ixx="8.3e-05" ixy="0.0" ixz="-0.0" iyy="0.000118" iyz="-9e-06" izz="4.1e-05"/>
  </inertial>
  <visual>
    <origin rpy="0 0 0" xyz="-0.0 -0.0039 -0.292"/>
    <geometry>
      <mesh filename="package://deep_ballbot_description/meshes/rasbperry_pi_1.stl" scale="0.001 0.001 0.001"/>
    </geometry>
    <material name="silver"/>
  </visual>
  <collision>
    <origin rpy="0 0 0" xyz="-0.0 -0.0039 -0.292"/>
    <geometry>
      <mesh filename="package://deep_ballbot_description/meshes/rasbperry_pi_1.stl" scale="0.001 0.001 0.001"/>
    </geometry>
  </collision>
</link>

<link name="motor_mount1_1">
  <inertial>
    <origin rpy="0 0 0" xyz="0.008784093083896216 -0.005071216542772684 -0.01575982915390231"/>
    <mass value="0.08608420182582005"/>
    <inertia ixx="3.8e-05" ixy="-9e-06" ixz="1e-05" iyy="2.8e-05" iyz="-6e-06" izz="4.3e-05"/>
  </inertial>
  <visual>
    <origin rpy="0 0 0" xyz="0.046487 -0.026839 -0.171056"/>
    <geometry>
      <mesh filename="package://deep_ballbot_description/meshes/motor_mount1_1.stl" scale="0.001 0.001 0.001"/>
    </geometry>
    <material name="silver"/>
  </visual>
  <collision>
    <origin rpy="0 0 0" xyz="0.046487 -0.026839 -0.171056"/>
    <geometry>
      <mesh filename="package://deep_ballbot_description/meshes/motor_mount1_1.stl" scale="0.001 0.001 0.001"/>
    </geometry>
  </collision>
</link>

<link name="motor_mount2_1">
  <inertial>
    <origin rpy="0 0 0" xyz="1.2758713609389452e-14 0.010142433085668257 -0.01575982915375221"/>
    <mass value="0.08608420182581958"/>
    <inertia ixx="2.3e-05" ixy="0.0" ixz="-0.0" iyy="4.3e-05" iyz="1.1e-05" izz="4.3e-05"/>
  </inertial>
  <visual>
    <origin rpy="0 0 0" xyz="-0.0 0.053678 -0.171056"/>
    <geometry>
      <mesh filename="package://deep_ballbot_description/meshes/motor_mount2_1.stl" scale="0.001 0.001 0.001"/>
    </geometry>
    <material name="silver"/>
  </visual>
  <collision>
    <origin rpy="0 0 0" xyz="-0.0 0.053678 -0.171056"/>
    <geometry>
      <mesh filename="package://deep_ballbot_description/meshes/motor_mount2_1.stl" scale="0.001 0.001 0.001"/>
    </geometry>
  </collision>
</link>

<link name="motor_mount3_1">
  <inertial>
    <origin rpy="0 0 0" xyz="-0.008784093083910476 -0.005071216542747357 -0.015759829153902005"/>
    <mass value="0.08608420182581962"/>
    <inertia ixx="3.8e-05" ixy="9e-06" ixz="-1e-05" iyy="2.8e-05" iyz="-6e-06" izz="4.3e-05"/>
  </inertial>
  <visual>
    <origin rpy="0 0 0" xyz="-0.046487 -0.026839 -0.171056"/>
    <geometry>
      <mesh filename="package://deep_ballbot_description/meshes/motor_mount3_1.stl" scale="0.001 0.001 0.001"/>
    </geometry>
    <material name="silver"/>
  </visual>
  <collision>
    <origin rpy="0 0 0" xyz="-0.046487 -0.026839 -0.171056"/>
    <geometry>
      <mesh filename="package://deep_ballbot_description/meshes/motor_mount3_1.stl" scale="0.001 0.001 0.001"/>
    </geometry>
  </collision>
</link>

<link name="motor_stator2_1">
  <inertial>
    <origin rpy="0 0 0" xyz="3.454227324397115e-17 0.015087302537697307 -0.016105881234574987"/>
    <mass value="0.20718917948399745"/>
    <inertia ixx="4.2e-05" ixy="0.0" ixz="-0.0" iyy="6.1e-05" iyz="1.8e-05" izz="6.1e-05"/>
  </inertial>
  <visual>
    <origin rpy="0 0 0" xyz="-0.0 0.059335 -0.165399"/>
    <geometry>
      <mesh filename="package://deep_ballbot_description/meshes/motor_stator2_1.stl" scale="0.001 0.001 0.001"/>
    </geometry>
    <material name="silver"/>
  </visual>
  <collision>
    <origin rpy="0 0 0" xyz="-0.0 0.059335 -0.165399"/>
    <geometry>
      <mesh filename="package://deep_ballbot_description/meshes/motor_stator2_1.stl" scale="0.001 0.001 0.001"/>
    </geometry>
  </collision>
</link>

<link name="motor_stator3_1">
  <inertial>
    <origin rpy="0 0 0" xyz="-0.013066369938677776 -0.007543151268848681 -0.01610588123457521"/>
    <mass value="0.2071891794839975"/>
    <inertia ixx="5.6e-05" ixy="8e-06" ixz="-1.6e-05" iyy="4.7e-05" iyz="-9e-06" izz="6.1e-05"/>
  </inertial>
  <visual>
    <origin rpy="0 0 0" xyz="-0.051386 -0.029667 -0.165399"/>
    <geometry>
      <mesh filename="package://deep_ballbot_description/meshes/motor_stator3_1.stl" scale="0.001 0.001 0.001"/>
    </geometry>
    <material name="silver"/>
  </visual>
  <collision>
    <origin rpy="0 0 0" xyz="-0.051386 -0.029667 -0.165399"/>
    <geometry>
      <mesh filename="package://deep_ballbot_description/meshes/motor_stator3_1.stl" scale="0.001 0.001 0.001"/>
    </geometry>
  </collision>
</link>

<link name="motor_stator1_1">
  <inertial>
    <origin rpy="0 0 0" xyz="0.013066369938678046 -0.007543151268848507 -0.016105881234575237"/>
    <mass value="0.2071891794839974"/>
    <inertia ixx="5.6e-05" ixy="-8e-06" ixz="1.6e-05" iyy="4.7e-05" iyz="-9e-06" izz="6.1e-05"/>
  </inertial>
  <visual>
    <origin rpy="0 0 0" xyz="0.051386 -0.029667 -0.165399"/>
    <geometry>
      <mesh filename="package://deep_ballbot_description/meshes/motor_stator1_1.stl" scale="0.001 0.001 0.001"/>
    </geometry>
    <material name="silver"/>
  </visual>
  <collision>
    <origin rpy="0 0 0" xyz="0.051386 -0.029667 -0.165399"/>
    <geometry>
      <mesh filename="package://deep_ballbot_description/meshes/motor_stator1_1.stl" scale="0.001 0.001 0.001"/>
    </geometry>
  </collision>
</link>

<link name="motor_rotor1_1">
  <inertial>
    <origin rpy="0 0 0" xyz="-0.005759360727442257 0.003325011462291614 -0.009651244658309549"/>
    <mass value="0.37818287206036283"/>
    <inertia ixx="0.000136" ixy="-1.9e-05" ixz="3.7e-05" iyy="0.000115" iyz="-2.1e-05" izz="0.000147"/>
  </inertial>
  <visual>
    <origin rpy="0 0 0" xyz="0.041588 -0.024011 -0.148601"/>
    <geometry>
      <mesh filename="package://deep_ballbot_description/meshes/motor_rotor1_1.stl" scale="0.001 0.001 0.001"/>
    </geometry>
    <material name="silver"/>
  </visual>
  <collision>
    <origin rpy="0 0 0" xyz="0.041588 -0.024011 -0.148601"/>
    <geometry>
      <mesh filename="package://deep_ballbot_description/meshes/motor_rotor1_1.stl" scale="0.001 0.001 0.001"/>
    </geometry>
  </collision>
</link>

<link name="motor_rotor2_1">
  <inertial>
    <origin rpy="0 0 0" xyz="-7.656393366881626e-13 -0.006651022923256242 -0.009651244658309799"/>
    <mass value="0.37818287206036244"/>
    <inertia ixx="0.000104" ixy="-0.0" ixz="-0.0" iyy="0.000147" iyz="4.3e-05" izz="0.000147"/>
  </inertial>
  <visual>
    <origin rpy="0 0 0" xyz="-0.0 0.048021 -0.148601"/>
    <geometry>
      <mesh filename="package://deep_ballbot_description/meshes/motor_rotor2_1.stl" scale="0.001 0.001 0.001"/>
    </geometry>
    <material name="silver"/>
  </visual>
  <collision>
    <origin rpy="0 0 0" xyz="-0.0 0.048021 -0.148601"/>
    <geometry>
      <mesh filename="package://deep_ballbot_description/meshes/motor_rotor2_1.stl" scale="0.001 0.001 0.001"/>
    </geometry>
  </collision>
</link>

<link name="motor_rotor3_1">
  <inertial>
    <origin rpy="0 0 0" xyz="0.0057593607282081655 0.003325011460965234 -0.009651244658309466"/>
    <mass value="0.37818287206036283"/>
    <inertia ixx="0.000136" ixy="1.9e-05" ixz="-3.7e-05" iyy="0.000115" iyz="-2.1e-05" izz="0.000147"/>
  </inertial>
  <visual>
    <origin rpy="0 0 0" xyz="-0.041588 -0.024011 -0.148601"/>
    <geometry>
      <mesh filename="package://deep_ballbot_description/meshes/motor_rotor3_1.stl" scale="0.001 0.001 0.001"/>
    </geometry>
    <material name="silver"/>
  </visual>
  <collision>
    <origin rpy="0 0 0" xyz="-0.041588 -0.024011 -0.148601"/>
    <geometry>
      <mesh filename="package://deep_ballbot_description/meshes/motor_rotor3_1.stl" scale="0.001 0.001 0.001"/>
    </geometry>
  </collision>
</link>

<link name="wheel_body3_1">
  <inertial>
    <origin rpy="0 0 0" xyz="0.007006872776695441 0.004021283361320155 -0.011113046962438769"/>
    <mass value="0.017119124264976984"/>
    <inertia ixx="4e-06" ixy="1e-06" ixz="-1e-06" iyy="4e-06" iyz="-1e-06" izz="5e-06"/>
  </inertial>
  <visual>
    <origin rpy="0 0 0" xyz="-0.052855 -0.030516 -0.13559"/>
    <geometry>
      <mesh filename="package://deep_ballbot_description/meshes/wheel_body3_1.stl" scale="0.001 0.001 0.001"/>
    </geometry>
    <material name="silver"/>
  </visual>
  <collision>
    <origin rpy="0 0 0" xyz="-0.052855 -0.030516 -0.13559"/>
    <geometry>
      <mesh filename="package://deep_ballbot_description/meshes/wheel_body3_1.stl" scale="0.001 0.001 0.001"/>
    </geometry>
  </collision>
</link>

<link name="wheel_body2_1">
  <inertial>
    <origin rpy="0 0 0" xyz="-2.0618457227382734e-05 -0.008078140713205964 -0.01111353172235481"/>
    <mass value="0.01711866259314613"/>
    <inertia ixx="3e-06" ixy="-0.0" ixz="0.0" iyy="5e-06" iyz="2e-06" izz="5e-06"/>
  </inertial>
  <visual>
    <origin rpy="0 0 0" xyz="-0.0 0.061032 -0.13559"/>
    <geometry>
      <mesh filename="package://deep_ballbot_description/meshes/wheel_body2_1.stl" scale="0.001 0.001 0.001"/>
    </geometry>
    <material name="silver"/>
  </visual>
  <collision>
    <origin rpy="0 0 0" xyz="-0.0 0.061032 -0.13559"/>
    <geometry>
      <mesh filename="package://deep_ballbot_description/meshes/wheel_body2_1.stl" scale="0.001 0.001 0.001"/>
    </geometry>
  </collision>
</link>

<link name="wheel_body1_1">
  <inertial>
    <origin rpy="0 0 0" xyz="-0.006985828103879044 0.00405692649815205 -0.011113531998728846"/>
    <mass value="0.01711866246905899"/>
    <inertia ixx="4e-06" ixy="-1e-06" ixz="1e-06" iyy="4e-06" iyz="-1e-06" izz="5e-06"/>
  </inertial>
  <visual>
    <origin rpy="0 0 0" xyz="0.052855 -0.030516 -0.13559"/>
    <geometry>
      <mesh filename="package://deep_ballbot_description/meshes/wheel_body1_1.stl" scale="0.001 0.001 0.001"/>
    </geometry>
    <material name="silver"/>
  </visual>
  <collision>
    <origin rpy="0 0 0" xyz="0.052855 -0.030516 -0.13559"/>
    <geometry>
      <mesh filename="package://deep_ballbot_description/meshes/wheel_body1_1.stl" scale="0.001 0.001 0.001"/>
    </geometry>
  </collision>
</link>

<link name="wheel_roller1.10_1">
  <inertial>
    <origin rpy="0 0 0" xyz="3.5748547961428345e-07 -3.6339927950504447e-07 9.819223648066533e-08"/>
    <mass value="0.001201137707108164"/>
    <inertia ixx="0.0" ixy="-0.0" ixz="0.0" iyy="0.0" iyz="0.0" izz="0.0"/>
  </inertial>
  <visual>
    <origin rpy="0 0 0" xyz="0.041588 -0.024011 -0.103174"/>
    <geometry>
      <mesh filename="package://deep_ballbot_description/meshes/wheel_roller1.10_1.stl" scale="0.001 0.001 0.001"/>
    </geometry>
    <material name="silver"/>
  </visual>
  <collision>
    <origin rpy="0 0 0" xyz="0.041588 -0.024011 -0.103174"/>
    <geometry>
      <mesh filename="package://deep_ballbot_description/meshes/wheel_roller1.10_1.stl" scale="0.001 0.001 0.001"/>
    </geometry>
  </collision>
</link>

<link name="wheel_roller1.4_1">
  <inertial>
    <origin rpy="0 0 0" xyz="0.0006668609842473971 -0.0018856180530574876 -0.002540244265176489"/>
    <mass value="0.0025623256301060106"/>
    <inertia ixx="0.0" ixy="0.0" ixz="0.0" iyy="0.0" iyz="0.0" izz="0.0"/>
  </inertial>
  <visual>
    <origin rpy="0 0 0" xyz="0.081103 -0.03322 -0.14302"/>
    <geometry>
      <mesh filename="package://deep_ballbot_description/meshes/wheel_roller1.4_1.stl" scale="0.001 0.001 0.001"/>
    </geometry>
    <material name="silver"/>
  </visual>
  <collision>
    <origin rpy="0 0 0" xyz="0.081103 -0.03322 -0.14302"/>
    <geometry>
      <mesh filename="package://deep_ballbot_description/meshes/wheel_roller1.4_1.stl" scale="0.001 0.001 0.001"/>
    </geometry>
  </collision>
</link>

<link name="wheel_roller1.9_1">
  <inertial>
    <origin rpy="0 0 0" xyz="2.1682235354369972e-07 -4.608225921444442e-07 -9.665432668115592e-08"/>
    <mass value="0.0012011377071081259"/>
    <inertia ixx="0.0" ixy="0.0" ixz="0.0" iyy="0.0" iyz="-0.0" izz="0.0"/>
  </inertial>
  <visual>
    <origin rpy="0 0 0" xyz="0.082135 -0.017421 -0.134994"/>
    <geometry>
      <mesh filename="package://deep_ballbot_description/meshes/wheel_roller1.9_1.stl" scale="0.001 0.001 0.001"/>
    </geometry>
    <material name="silver"/>
  </visual>
  <collision>
    <origin rpy="0 0 0" xyz="0.082135 -0.017421 -0.134994"/>
    <geometry>
      <mesh filename="package://deep_ballbot_description/meshes/wheel_roller1.9_1.stl" scale="0.001 0.001 0.001"/>
    </geometry>
  </collision>
</link>

<link name="wheel_roller1.5_1">
  <inertial>
    <origin rpy="0 0 0" xyz="4.5717992872007507e-07 -4.655576237282827e-07 6.072471998852524e-08"/>
    <mass value="0.0025623256301060215"/>
    <inertia ixx="0.0" ixy="0.0" ixz="-0.0" iyy="0.0" iyz="-0.0" izz="0.0"/>
  </inertial>
  <visual>
    <origin rpy="0 0 0" xyz="0.052608 -0.015208 -0.108316"/>
    <geometry>
      <mesh filename="package://deep_ballbot_description/meshes/wheel_roller1.5_1.stl" scale="0.001 0.001 0.001"/>
    </geometry>
    <material name="silver"/>
  </visual>
  <collision>
    <origin rpy="0 0 0" xyz="0.052608 -0.015208 -0.108316"/>
    <geometry>
      <mesh filename="package://deep_ballbot_description/meshes/wheel_roller1.5_1.stl" scale="0.001 0.001 0.001"/>
    </geometry>
  </collision>
</link>

<link name="wheel_roller1.3_1">
  <inertial>
    <origin rpy="0 0 0" xyz="1.844145142218534e-07 4.0516786578570496e-07 3.0162779174336407e-07"/>
    <mass value="0.0025623256301059937"/>
    <inertia ixx="0.0" ixy="-0.0" ixz="-0.0" iyy="0.0" iyz="0.0" izz="0.0"/>
  </inertial>
  <visual>
    <origin rpy="0 0 0" xyz="0.046834 -0.05735 -0.124387"/>
    <geometry>
      <mesh filename="package://deep_ballbot_description/meshes/wheel_roller1.3_1.stl" scale="0.001 0.001 0.001"/>
    </geometry>
    <material name="silver"/>
  </visual>
  <collision>
    <origin rpy="0 0 0" xyz="0.046834 -0.05735 -0.124387"/>
    <geometry>
      <mesh filename="package://deep_ballbot_description/meshes/wheel_roller1.3_1.stl" scale="0.001 0.001 0.001"/>
    </geometry>
  </collision>
</link>

<link name="wheel_roller1.6_1">
  <inertial>
    <origin rpy="0 0 0" xyz="-1.5083097651413802e-07 4.3352494309700784e-07 -4.7480970863378325e-07"/>
    <mass value="0.0025623256301060132"/>
    <inertia ixx="0.0" ixy="0.0" ixz="0.0" iyy="0.0" iyz="0.0" izz="0.0"/>
  </inertial>
  <visual>
    <origin rpy="0 0 0" xyz="0.039475 -0.037946 -0.108313"/>
    <geometry>
      <mesh filename="package://deep_ballbot_description/meshes/wheel_roller1.6_1.stl" scale="0.001 0.001 0.001"/>
    </geometry>
    <material name="silver"/>
  </visual>
  <collision>
    <origin rpy="0 0 0" xyz="0.039475 -0.037946 -0.108313"/>
    <geometry>
      <mesh filename="package://deep_ballbot_description/meshes/wheel_roller1.6_1.stl" scale="0.001 0.001 0.001"/>
    </geometry>
  </collision>
</link>

<link name="wheel_roller1.8_1">
  <inertial>
    <origin rpy="0 0 0" xyz="-2.1064078446764167e-08 -4.608225138910682e-07 -9.665432521011041e-08"/>
    <mass value="0.0012011377071081484"/>
    <inertia ixx="0.0" ixy="-0.0" ixz="0.0" iyy="0.0" iyz="0.0" izz="0.0"/>
  </inertial>
  <visual>
    <origin rpy="0 0 0" xyz="0.056154 -0.062421 -0.134994"/>
    <geometry>
      <mesh filename="package://deep_ballbot_description/meshes/wheel_roller1.8_1.stl" scale="0.001 0.001 0.001"/>
    </geometry>
    <material name="silver"/>
  </visual>
  <collision>
    <origin rpy="0 0 0" xyz="0.056154 -0.062421 -0.134994"/>
    <geometry>
      <mesh filename="package://deep_ballbot_description/meshes/wheel_roller1.8_1.stl" scale="0.001 0.001 0.001"/>
    </geometry>
  </collision>
</link>

<link name="wheel_roller1.7_1">
  <inertial>
    <origin rpy="0 0 0" xyz="1.844145553070442e-07 7.146925377725377e-08 3.016277919654087e-07"/>
    <mass value="0.0025623256301059846"/>
    <inertia ixx="0.0" ixy="-0.0" ixz="-0.0" iyy="0.0" iyz="0.0" izz="0.0"/>
  </inertial>
  <visual>
    <origin rpy="0 0 0" xyz="0.073084 -0.011884 -0.124387"/>
    <geometry>
      <mesh filename="package://deep_ballbot_description/meshes/wheel_roller1.7_1.stl" scale="0.001 0.001 0.001"/>
    </geometry>
    <material name="silver"/>
  </visual>
  <collision>
    <origin rpy="0 0 0" xyz="0.073084 -0.011884 -0.124387"/>
    <geometry>
      <mesh filename="package://deep_ballbot_description/meshes/wheel_roller1.7_1.stl" scale="0.001 0.001 0.001"/>
    </geometry>
  </collision>
</link>

<link name="wheel_roller1.1_1">
  <inertial>
    <origin rpy="0 0 0" xyz="-4.803400587699569e-07 2.099616943501692e-07 7.806477039795645e-08"/>
    <mass value="0.0025623256301060197"/>
    <inertia ixx="0.0" ixy="0.0" ixz="-0.0" iyy="0.0" iyz="-0.0" izz="0.0"/>
  </inertial>
  <visual>
    <origin rpy="0 0 0" xyz="0.067317 -0.054021 -0.140462"/>
    <geometry>
      <mesh filename="package://deep_ballbot_description/meshes/wheel_roller1.1_1.stl" scale="0.001 0.001 0.001"/>
    </geometry>
    <material name="silver"/>
  </visual>
  <collision>
    <origin rpy="0 0 0" xyz="0.067317 -0.054021 -0.140462"/>
    <geometry>
      <mesh filename="package://deep_ballbot_description/meshes/wheel_roller1.1_1.stl" scale="0.001 0.001 0.001"/>
    </geometry>
  </collision>
</link>

<link name="wheel_roller1.2_1">
  <inertial>
    <origin rpy="0 0 0" xyz="1.1343589706447332e-08 -1.5996360114289843e-07 -4.949366527451371e-07"/>
    <mass value="0.0012011377071081658"/>
    <inertia ixx="0.0" ixy="-0.0" ixz="0.0" iyy="0.0" iyz="-0.0" izz="0.0"/>
  </inertial>
  <visual>
    <origin rpy="0 0 0" xyz="0.07833 -0.045224 -0.145601"/>
    <geometry>
      <mesh filename="package://deep_ballbot_description/meshes/wheel_roller1.2_1.stl" scale="0.001 0.001 0.001"/>
    </geometry>
    <material name="silver"/>
  </visual>
  <collision>
    <origin rpy="0 0 0" xyz="0.07833 -0.045224 -0.145601"/>
    <geometry>
      <mesh filename="package://deep_ballbot_description/meshes/wheel_roller1.2_1.stl" scale="0.001 0.001 0.001"/>
    </geometry>
  </collision>
</link>

<link name="wheel_roller1.12_1">
  <inertial>
    <origin rpy="0 0 0" xyz="-4.134077118134183e-07 -3.3080520736410157e-07 -1.763657338921254e-07"/>
    <mass value="0.0012011377071081525"/>
    <inertia ixx="0.0" ixy="-0.0" ixz="0.0" iyy="0.0" iyz="0.0" izz="0.0"/>
  </inertial>
  <visual>
    <origin rpy="0 0 0" xyz="0.063771 -0.006813 -0.113787"/>
    <geometry>
      <mesh filename="package://deep_ballbot_description/meshes/wheel_roller1.12_1.stl" scale="0.001 0.001 0.001"/>
    </geometry>
    <material name="silver"/>
  </visual>
  <collision>
    <origin rpy="0 0 0" xyz="0.063771 -0.006813 -0.113787"/>
    <geometry>
      <mesh filename="package://deep_ballbot_description/meshes/wheel_roller1.12_1.stl" scale="0.001 0.001 0.001"/>
    </geometry>
  </collision>
</link>

<link name="wheel_roller1.11_1">
  <inertial>
    <origin rpy="0 0 0" xyz="1.5200671590887005e-07 -6.254028863533767e-08 -3.000900889310598e-07"/>
    <mass value="0.001201137707108158"/>
    <inertia ixx="0.0" ixy="0.0" ixz="0.0" iyy="0.0" iyz="-0.0" izz="0.0"/>
  </inertial>
  <visual>
    <origin rpy="0 0 0" xyz="0.037783 -0.051814 -0.113781"/>
    <geometry>
      <mesh filename="package://deep_ballbot_description/meshes/wheel_roller1.11_1.stl" scale="0.001 0.001 0.001"/>
    </geometry>
    <material name="silver"/>
  </visual>
  <collision>
    <origin rpy="0 0 0" xyz="0.037783 -0.051814 -0.113781"/>
    <geometry>
      <mesh filename="package://deep_ballbot_description/meshes/wheel_roller1.11_1.stl" scale="0.001 0.001 0.001"/>
    </geometry>
  </collision>
</link>

<link name="wheel_roller2.12_1">
  <inertial>
    <origin rpy="0 0 0" xyz="-4.106784357027493e-14 -4.7663711798262565e-07 3.0162779128539707e-07"/>
    <mass value="0.002562325630106007"/>
    <inertia ixx="0.0" ixy="0.0" ixz="0.0" iyy="0.0" iyz="-0.0" izz="0.0"/>
  </inertial>
  <visual>
    <origin rpy="0 0 0" xyz="-0.02625 0.069234 -0.124387"/>
    <geometry>
      <mesh filename="package://deep_ballbot_description/meshes/wheel_roller2.12_1.stl" scale="0.001 0.001 0.001"/>
    </geometry>
    <material name="silver"/>
  </visual>
  <collision>
    <origin rpy="0 0 0" xyz="-0.02625 0.069234 -0.124387"/>
    <geometry>
      <mesh filename="package://deep_ballbot_description/meshes/wheel_roller2.12_1.stl" scale="0.001 0.001 0.001"/>
    </geometry>
  </collision>
</link>

<link name="wheel_roller2.9_1">
  <inertial>
    <origin rpy="0 0 0" xyz="-2.3788655468745534e-07 1.3562870757044543e-09 -1.763656140435499e-07"/>
    <mass value="0.0012011377071081688"/>
    <inertia ixx="0.0" ixy="0.0" ixz="-0.0" iyy="0.0" iyz="0.0" izz="0.0"/>
  </inertial>
  <visual>
    <origin rpy="0 0 0" xyz="-0.025986 0.058634 -0.113787"/>
    <geometry>
      <mesh filename="package://deep_ballbot_description/meshes/wheel_roller2.9_1.stl" scale="0.001 0.001 0.001"/>
    </geometry>
    <material name="silver"/>
  </visual>
  <collision>
    <origin rpy="0 0 0" xyz="-0.025986 0.058634 -0.113787"/>
    <geometry>
      <mesh filename="package://deep_ballbot_description/meshes/wheel_roller2.9_1.stl" scale="0.001 0.001 0.001"/>
    </geometry>
  </collision>
</link>

<link name="wheel_roller2.11_1">
  <inertial>
    <origin rpy="0 0 0" xyz="2.3788655226578137e-07 1.250806447097852e-07 -3.0008997174701957e-07"/>
    <mass value="0.0012011377071081777"/>
    <inertia ixx="0.0" ixy="-0.0" ixz="0.0" iyy="0.0" iyz="0.0" izz="0.0"/>
  </inertial>
  <visual>
    <origin rpy="0 0 0" xyz="0.025981 0.058628 -0.113781"/>
    <geometry>
      <mesh filename="package://deep_ballbot_description/meshes/wheel_roller2.11_1.stl" scale="0.001 0.001 0.001"/>
    </geometry>
    <material name="silver"/>
  </visual>
  <collision>
    <origin rpy="0 0 0" xyz="0.025981 0.058628 -0.113781"/>
    <geometry>
      <mesh filename="package://deep_ballbot_description/meshes/wheel_roller2.11_1.stl" scale="0.001 0.001 0.001"/>
    </geometry>
  </collision>
</link>

<link name="wheel_roller2.3_1">
  <inertial>
    <origin rpy="0 0 0" xyz="4.121009089530503e-14 -4.766371196063268e-07 3.0162779197928646e-07"/>
    <mass value="0.0025623256301060154"/>
    <inertia ixx="0.0" ixy="-0.0" ixz="0.0" iyy="0.0" iyz="-0.0" izz="0.0"/>
  </inertial>
  <visual>
    <origin rpy="0 0 0" xyz="0.02625 0.069234 -0.124387"/>
    <geometry>
      <mesh filename="package://deep_ballbot_description/meshes/wheel_roller2.3_1.stl" scale="0.001 0.001 0.001"/>
    </geometry>
    <material name="silver"/>
  </visual>
  <collision>
    <origin rpy="0 0 0" xyz="0.02625 0.069234 -0.124387"/>
    <geometry>
      <mesh filename="package://deep_ballbot_description/meshes/wheel_roller2.3_1.stl" scale="0.001 0.001 0.001"/>
    </geometry>
  </collision>
</link>

<link name="wheel_roller2.10_1">
  <inertial>
    <origin rpy="0 0 0" xyz="5.878978068805001e-17 -2.732015632819773e-07 9.819211309325393e-08"/>
    <mass value="0.0012011377071081241"/>
    <inertia ixx="0.0" ixy="0.0" ixz="-0.0" iyy="0.0" iyz="0.0" izz="0.0"/>
  </inertial>
  <visual>
    <origin rpy="0 0 0" xyz="-0.0 0.048021 -0.103174"/>
    <geometry>
      <mesh filename="package://deep_ballbot_description/meshes/wheel_roller2.10_1.stl" scale="0.001 0.001 0.001"/>
    </geometry>
    <material name="silver"/>
  </visual>
  <collision>
    <origin rpy="0 0 0" xyz="-0.0 0.048021 -0.103174"/>
    <geometry>
      <mesh filename="package://deep_ballbot_description/meshes/wheel_roller2.10_1.stl" scale="0.001 0.001 0.001"/>
    </geometry>
  </collision>
</link>

<link name="wheel_roller2.5_1">
  <inertial>
    <origin rpy="0 0 0" xyz="-3.397459970803235e-07 -2.35734216522121e-07 6.072436552206906e-08"/>
    <mass value="0.0025623256301060093"/>
    <inertia ixx="0.0" ixy="-0.0" ixz="0.0" iyy="0.0" iyz="-0.0" izz="0.0"/>
  </inertial>
  <visual>
    <origin rpy="0 0 0" xyz="-0.013134 0.053163 -0.108316"/>
    <geometry>
      <mesh filename="package://deep_ballbot_description/meshes/wheel_roller2.5_1.stl" scale="0.001 0.001 0.001"/>
    </geometry>
    <material name="silver"/>
  </visual>
  <collision>
    <origin rpy="0 0 0" xyz="-0.013134 0.053163 -0.108316"/>
    <geometry>
      <mesh filename="package://deep_ballbot_description/meshes/wheel_roller2.5_1.stl" scale="0.001 0.001 0.001"/>
    </geometry>
  </collision>
</link>

<link name="wheel_roller2.6_1">
  <inertial>
    <origin rpy="0 0 0" xyz="3.717165464323102e-14 2.9979968900473164e-07 -4.748095401990726e-07"/>
    <mass value="0.002562325630106006"/>
    <inertia ixx="0.0" ixy="0.0" ixz="-0.0" iyy="0.0" iyz="-0.0" izz="0.0"/>
  </inertial>
  <visual>
    <origin rpy="0 0 0" xyz="0.013125 0.05316 -0.108313"/>
    <geometry>
      <mesh filename="package://deep_ballbot_description/meshes/wheel_roller2.6_1.stl" scale="0.001 0.001 0.001"/>
    </geometry>
    <material name="silver"/>
  </visual>
  <collision>
    <origin rpy="0 0 0" xyz="0.013125 0.05316 -0.108313"/>
    <geometry>
      <mesh filename="package://deep_ballbot_description/meshes/wheel_roller2.6_1.stl" scale="0.001 0.001 0.001"/>
    </geometry>
  </collision>
</link>

<link name="wheel_roller2.2_1">
  <inertial>
    <origin rpy="0 0 0" xyz="3.3314595911284344e-17 3.199273256454527e-07 -4.949365298434483e-07"/>
    <mass value="0.001201137707108136"/>
    <inertia ixx="0.0" ixy="-0.0" ixz="0.0" iyy="0.0" iyz="-0.0" izz="0.0"/>
  </inertial>
  <visual>
    <origin rpy="0 0 0" xyz="-0.0 0.090448 -0.145601"/>
    <geometry>
      <mesh filename="package://deep_ballbot_description/meshes/wheel_roller2.2_1.stl" scale="0.001 0.001 0.001"/>
    </geometry>
    <material name="silver"/>
  </visual>
  <collision>
    <origin rpy="0 0 0" xyz="-0.0 0.090448 -0.145601"/>
    <geometry>
      <mesh filename="package://deep_ballbot_description/meshes/wheel_roller2.2_1.stl" scale="0.001 0.001 0.001"/>
    </geometry>
  </collision>
</link>

<link name="wheel_roller2.1_1">
  <inertial>
    <origin rpy="0 0 0" xyz="3.7544620190566036e-14 -2.5307392778617377e-07 7.806512442032343e-08"/>
    <mass value="0.002562325630106022"/>
    <inertia ixx="0.0" ixy="-0.0" ixz="0.0" iyy="0.0" iyz="-0.0" izz="0.0"/>
  </inertial>
  <visual>
    <origin rpy="0 0 0" xyz="0.013125 0.085309 -0.140462"/>
    <geometry>
      <mesh filename="package://deep_ballbot_description/meshes/wheel_roller2.1_1.stl" scale="0.001 0.001 0.001"/>
    </geometry>
    <material name="silver"/>
  </visual>
  <collision>
    <origin rpy="0 0 0" xyz="0.013125 0.085309 -0.140462"/>
    <geometry>
      <mesh filename="package://deep_ballbot_description/meshes/wheel_roller2.1_1.stl" scale="0.001 0.001 0.001"/>
    </geometry>
  </collision>
</link>

<link name="wheel_roller2.7_1">
  <inertial>
    <origin rpy="0 0 0" xyz="-2.3788655217557575e-07 -7.83548818050761e-08 -9.665444469786344e-08"/>
    <mass value="0.0012011377071081708"/>
    <inertia ixx="0.0" ixy="-0.0" ixz="0.0" iyy="0.0" iyz="0.0" izz="0.0"/>
  </inertial>
  <visual>
    <origin rpy="0 0 0" xyz="-0.025981 0.079841 -0.134994"/>
    <geometry>
      <mesh filename="package://deep_ballbot_description/meshes/wheel_roller2.7_1.stl" scale="0.001 0.001 0.001"/>
    </geometry>
    <material name="silver"/>
  </visual>
  <collision>
    <origin rpy="0 0 0" xyz="-0.025981 0.079841 -0.134994"/>
    <geometry>
      <mesh filename="package://deep_ballbot_description/meshes/wheel_roller2.7_1.stl" scale="0.001 0.001 0.001"/>
    </geometry>
  </collision>
</link>

<link name="wheel_roller2.8_1">
  <inertial>
    <origin rpy="0 0 0" xyz="2.3788655466663866e-07 -7.835488115282008e-08 -9.66544453084861e-08"/>
    <mass value="0.0012011377071081413"/>
    <inertia ixx="0.0" ixy="0.0" ixz="-0.0" iyy="0.0" iyz="0.0" izz="0.0"/>
  </inertial>
  <visual>
    <origin rpy="0 0 0" xyz="0.025981 0.079841 -0.134994"/>
    <geometry>
      <mesh filename="package://deep_ballbot_description/meshes/wheel_roller2.8_1.stl" scale="0.001 0.001 0.001"/>
    </geometry>
    <material name="silver"/>
  </visual>
  <collision>
    <origin rpy="0 0 0" xyz="0.025981 0.079841 -0.134994"/>
    <geometry>
      <mesh filename="package://deep_ballbot_description/meshes/wheel_roller2.8_1.stl" scale="0.001 0.001 0.001"/>
    </geometry>
  </collision>
</link>

<link name="wheel_roller2.4_1">
  <inertial>
    <origin rpy="0 0 0" xyz="0.0012986987297727726 0.0015200692565425084 -0.0025402442653454926"/>
    <mass value="0.002562325630105998"/>
    <inertia ixx="0.0" ixy="0.0" ixz="-0.0" iyy="0.0" iyz="-0.0" izz="0.0"/>
  </inertial>
  <visual>
    <origin rpy="0 0 0" xyz="-0.011783 0.086847 -0.14302"/>
    <geometry>
      <mesh filename="package://deep_ballbot_description/meshes/wheel_roller2.4_1.stl" scale="0.001 0.001 0.001"/>
    </geometry>
    <material name="silver"/>
  </visual>
  <collision>
    <origin rpy="0 0 0" xyz="-0.011783 0.086847 -0.14302"/>
    <geometry>
      <mesh filename="package://deep_ballbot_description/meshes/wheel_roller2.4_1.stl" scale="0.001 0.001 0.001"/>
    </geometry>
  </collision>
</link>

<link name="wheel_roller3.12_1">
  <inertial>
    <origin rpy="0 0 0" xyz="-3.487058553228173e-07 3.2944890774461166e-07 -1.7636573078350093e-07"/>
    <mass value="0.001201137707108146"/>
    <inertia ixx="0.0" ixy="-0.0" ixz="-0.0" iyy="0.0" iyz="-0.0" izz="0.0"/>
  </inertial>
  <visual>
    <origin rpy="0 0 0" xyz="-0.037786 -0.051821 -0.113787"/>
    <geometry>
      <mesh filename="package://deep_ballbot_description/meshes/wheel_roller3.12_1.stl" scale="0.001 0.001 0.001"/>
    </geometry>
    <material name="silver"/>
  </visual>
  <collision>
    <origin rpy="0 0 0" xyz="-0.037786 -0.051821 -0.113787"/>
    <geometry>
      <mesh filename="package://deep_ballbot_description/meshes/wheel_roller3.12_1.stl" scale="0.001 0.001 0.001"/>
    </geometry>
  </collision>
</link>

<link name="wheel_roller3.10_1">
  <inertial>
    <origin rpy="0 0 0" xyz="-3.5748547950326115e-07 -3.6339927952586115e-07 9.819223660556542e-08"/>
    <mass value="0.0012011377071081497"/>
    <inertia ixx="0.0" ixy="0.0" ixz="0.0" iyy="0.0" iyz="0.0" izz="0.0"/>
  </inertial>
  <visual>
    <origin rpy="0 0 0" xyz="-0.041588 -0.024011 -0.103174"/>
    <geometry>
      <mesh filename="package://deep_ballbot_description/meshes/wheel_roller3.10_1.stl" scale="0.001 0.001 0.001"/>
    </geometry>
    <material name="silver"/>
  </visual>
  <collision>
    <origin rpy="0 0 0" xyz="-0.041588 -0.024011 -0.103174"/>
    <geometry>
      <mesh filename="package://deep_ballbot_description/meshes/wheel_roller3.10_1.stl" scale="0.001 0.001 0.001"/>
    </geometry>
  </collision>
</link>

<link name="wheel_roller3.6_1">
  <inertial>
    <origin rpy="0 0 0" xyz="1.5083087312461885e-07 2.666754254261605e-07 -4.748091854411829e-07"/>
    <mass value="0.002562325630105979"/>
    <inertia ixx="0.0" ixy="-0.0" ixz="0.0" iyy="0.0" iyz="-0.0" izz="0.0"/>
  </inertial>
  <visual>
    <origin rpy="0 0 0" xyz="-0.0526 -0.015213 -0.108313"/>
    <geometry>
      <mesh filename="package://deep_ballbot_description/meshes/wheel_roller3.6_1.stl" scale="0.001 0.001 0.001"/>
    </geometry>
    <material name="silver"/>
  </visual>
  <collision>
    <origin rpy="0 0 0" xyz="-0.0526 -0.015213 -0.108313"/>
    <geometry>
      <mesh filename="package://deep_ballbot_description/meshes/wheel_roller3.6_1.stl" scale="0.001 0.001 0.001"/>
    </geometry>
  </collision>
</link>

<link name="wheel_roller3.7_1">
  <inertial>
    <origin rpy="0 0 0" xyz="-1.8441451397205322e-07 4.0516786545957695e-07 3.0162779186826416e-07"/>
    <mass value="0.002562325630105985"/>
    <inertia ixx="0.0" ixy="0.0" ixz="0.0" iyy="0.0" iyz="0.0" izz="0.0"/>
  </inertial>
  <visual>
    <origin rpy="0 0 0" xyz="-0.046834 -0.05735 -0.124387"/>
    <geometry>
      <mesh filename="package://deep_ballbot_description/meshes/wheel_roller3.7_1.stl" scale="0.001 0.001 0.001"/>
    </geometry>
    <material name="silver"/>
  </visual>
  <collision>
    <origin rpy="0 0 0" xyz="-0.046834 -0.05735 -0.124387"/>
    <geometry>
      <mesh filename="package://deep_ballbot_description/meshes/wheel_roller3.7_1.stl" scale="0.001 0.001 0.001"/>
    </geometry>
  </collision>
</link>

<link name="wheel_roller3.3_1">
  <inertial>
    <origin rpy="0 0 0" xyz="-1.8441455466866596e-07 7.146925391429693e-08 3.016277923678645e-07"/>
    <mass value="0.002562325630105982"/>
    <inertia ixx="0.0" ixy="0.0" ixz="0.0" iyy="0.0" iyz="0.0" izz="0.0"/>
  </inertial>
  <visual>
    <origin rpy="0 0 0" xyz="-0.073084 -0.011884 -0.124387"/>
    <geometry>
      <mesh filename="package://deep_ballbot_description/meshes/wheel_roller3.3_1.stl" scale="0.001 0.001 0.001"/>
    </geometry>
    <material name="silver"/>
  </visual>
  <collision>
    <origin rpy="0 0 0" xyz="-0.073084 -0.011884 -0.124387"/>
    <geometry>
      <mesh filename="package://deep_ballbot_description/meshes/wheel_roller3.3_1.stl" scale="0.001 0.001 0.001"/>
    </geometry>
  </collision>
</link>

<link name="wheel_roller3.1_1">
  <inertial>
    <origin rpy="0 0 0" xyz="4.80339954839204e-07 4.311217709912496e-08 7.806529328524547e-08"/>
    <mass value="0.002562325630106003"/>
    <inertia ixx="0.0" ixy="-0.0" ixz="-0.0" iyy="0.0" iyz="0.0" izz="0.0"/>
  </inertial>
  <visual>
    <origin rpy="0 0 0" xyz="-0.080442 -0.031288 -0.140462"/>
    <geometry>
      <mesh filename="package://deep_ballbot_description/meshes/wheel_roller3.1_1.stl" scale="0.001 0.001 0.001"/>
    </geometry>
    <material name="silver"/>
  </visual>
  <collision>
    <origin rpy="0 0 0" xyz="-0.080442 -0.031288 -0.140462"/>
    <geometry>
      <mesh filename="package://deep_ballbot_description/meshes/wheel_roller3.1_1.stl" scale="0.001 0.001 0.001"/>
    </geometry>
  </collision>
</link>

<link name="wheel_roller3.11_1">
  <inertial>
    <origin rpy="0 0 0" xyz="-3.898931472540168e-07 -6.254036901461729e-08 -3.0009009185927304e-07"/>
    <mass value="0.0012011377071081616"/>
    <inertia ixx="0.0" ixy="0.0" ixz="-0.0" iyy="0.0" iyz="0.0" izz="0.0"/>
  </inertial>
  <visual>
    <origin rpy="0 0 0" xyz="-0.063764 -0.006814 -0.113781"/>
    <geometry>
      <mesh filename="package://deep_ballbot_description/meshes/wheel_roller3.11_1.stl" scale="0.001 0.001 0.001"/>
    </geometry>
    <material name="silver"/>
  </visual>
  <collision>
    <origin rpy="0 0 0" xyz="-0.063764 -0.006814 -0.113781"/>
    <geometry>
      <mesh filename="package://deep_ballbot_description/meshes/wheel_roller3.11_1.stl" scale="0.001 0.001 0.001"/>
    </geometry>
  </collision>
</link>

<link name="wheel_roller3.8_1">
  <inertial>
    <origin rpy="0 0 0" xyz="-2.1682235511188974e-07 -4.6082259080176824e-07 -9.665432837424603e-08"/>
    <mass value="0.0012011377071081688"/>
    <inertia ixx="0.0" ixy="-0.0" ixz="-0.0" iyy="0.0" iyz="-0.0" izz="0.0"/>
  </inertial>
  <visual>
    <origin rpy="0 0 0" xyz="-0.082135 -0.017421 -0.134994"/>
    <geometry>
      <mesh filename="package://deep_ballbot_description/meshes/wheel_roller3.8_1.stl" scale="0.001 0.001 0.001"/>
    </geometry>
    <material name="silver"/>
  </visual>
  <collision>
    <origin rpy="0 0 0" xyz="-0.082135 -0.017421 -0.134994"/>
    <geometry>
      <mesh filename="package://deep_ballbot_description/meshes/wheel_roller3.8_1.stl" scale="0.001 0.001 0.001"/>
    </geometry>
  </collision>
</link>

<link name="wheel_roller3.9_1">
  <inertial>
    <origin rpy="0 0 0" xyz="2.1064078072063896e-08 -4.608225118232778e-07 -9.665432434968757e-08"/>
    <mass value="0.0012011377071081484"/>
    <inertia ixx="0.0" ixy="0.0" ixz="-0.0" iyy="0.0" iyz="0.0" izz="0.0"/>
  </inertial>
  <visual>
    <origin rpy="0 0 0" xyz="-0.056154 -0.062421 -0.134994"/>
    <geometry>
      <mesh filename="package://deep_ballbot_description/meshes/wheel_roller3.9_1.stl" scale="0.001 0.001 0.001"/>
    </geometry>
    <material name="silver"/>
  </visual>
  <collision>
    <origin rpy="0 0 0" xyz="-0.056154 -0.062421 -0.134994"/>
    <geometry>
      <mesh filename="package://deep_ballbot_description/meshes/wheel_roller3.9_1.stl" scale="0.001 0.001 0.001"/>
    </geometry>
  </collision>
</link>

<link name="wheel_roller3.2_1">
  <inertial>
    <origin rpy="0 0 0" xyz="-1.1343589831347423e-08 -1.5996360136494303e-07 -4.949366527173815e-07"/>
    <mass value="0.0012011377071081653"/>
    <inertia ixx="0.0" ixy="0.0" ixz="-0.0" iyy="0.0" iyz="-0.0" izz="0.0"/>
  </inertial>
  <visual>
    <origin rpy="0 0 0" xyz="-0.07833 -0.045224 -0.145601"/>
    <geometry>
      <mesh filename="package://deep_ballbot_description/meshes/wheel_roller3.2_1.stl" scale="0.001 0.001 0.001"/>
    </geometry>
    <material name="silver"/>
  </visual>
  <collision>
    <origin rpy="0 0 0" xyz="-0.07833 -0.045224 -0.145601"/>
    <geometry>
      <mesh filename="package://deep_ballbot_description/meshes/wheel_roller3.2_1.stl" scale="0.001 0.001 0.001"/>
    </geometry>
  </collision>
</link>

<link name="wheel_roller3.5_1">
  <inertial>
    <origin rpy="0 0 0" xyz="-1.1743386531953837e-07 -2.9870810242665913e-07 6.072419658775807e-08"/>
    <mass value="0.0025623256301059998"/>
    <inertia ixx="0.0" ixy="-0.0" ixz="-0.0" iyy="0.0" iyz="0.0" izz="0.0"/>
  </inertial>
  <visual>
    <origin rpy="0 0 0" xyz="-0.039474 -0.037956 -0.108316"/>
    <geometry>
      <mesh filename="package://deep_ballbot_description/meshes/wheel_roller3.5_1.stl" scale="0.001 0.001 0.001"/>
    </geometry>
    <material name="silver"/>
  </visual>
  <collision>
    <origin rpy="0 0 0" xyz="-0.039474 -0.037956 -0.108316"/>
    <geometry>
      <mesh filename="package://deep_ballbot_description/meshes/wheel_roller3.5_1.stl" scale="0.001 0.001 0.001"/>
    </geometry>
  </collision>
</link>

<link name="wheel_roller3.4_1">
  <inertial>
    <origin rpy="0 0 0" xyz="-0.0019665597139539304 0.0003645487964586275 -0.0025402442656998203"/>
    <mass value="0.0025623256301060137"/>
    <inertia ixx="0.0" ixy="-0.0" ixz="0.0" iyy="0.0" iyz="-0.0" izz="0.0"/>
  </inertial>
  <visual>
    <origin rpy="0 0 0" xyz="-0.069321 -0.053628 -0.14302"/>
    <geometry>
      <mesh filename="package://deep_ballbot_description/meshes/wheel_roller3.4_1.stl" scale="0.001 0.001 0.001"/>
    </geometry>
    <material name="silver"/>
  </visual>
  <collision>
    <origin rpy="0 0 0" xyz="-0.069321 -0.053628 -0.14302"/>
    <geometry>
      <mesh filename="package://deep_ballbot_description/meshes/wheel_roller3.4_1.stl" scale="0.001 0.001 0.001"/>
    </geometry>
  </collision>
</link>

<link name="base_shell3_1">
  <inertial>
    <origin rpy="0 0 0" xyz="0.0315493029461081 0.01821499854867909 0.021364464404157207"/>
    <mass value="0.03897424370875779"/>
    <inertia ixx="3.3e-05" ixy="1.1e-05" ixz="-6e-06" iyy="2e-05" iyz="-3e-06" izz="3.8e-05"/>
  </inertial>
  <visual>
    <origin rpy="0 0 0" xyz="-0.0 -0.0 -0.139"/>
    <geometry>
      <mesh filename="package://deep_ballbot_description/meshes/base_shell3_1.stl" scale="0.001 0.001 0.001"/>
    </geometry>
    <material name="silver"/>
  </visual>
  <collision>
    <origin rpy="0 0 0" xyz="-0.0 -0.0 -0.139"/>
    <geometry>
      <mesh filename="package://deep_ballbot_description/meshes/base_shell3_1.stl" scale="0.001 0.001 0.001"/>
    </geometry>
  </collision>
</link>

<link name="arduino_mount1_1">
  <inertial>
    <origin rpy="0 0 0" xyz="-0.0017985403607222034 -0.0017781689855505562 -2.1615661864288205e-05"/>
    <mass value="0.023201510107992093"/>
    <inertia ixx="1.3e-05" ixy="5e-06" ixz="-0.0" iyy="8e-06" iyz="0.0" izz="1.2e-05"/>
  </inertial>
  <visual>
    <origin rpy="0 0 0" xyz="0.026519 0.015311 -0.2195"/>
    <geometry>
      <mesh filename="package://deep_ballbot_description/meshes/arduino_mount1_1.stl" scale="0.001 0.001 0.001"/>
    </geometry>
    <material name="silver"/>
  </visual>
  <collision>
    <origin rpy="0 0 0" xyz="0.026519 0.015311 -0.2195"/>
    <geometry>
      <mesh filename="package://deep_ballbot_description/meshes/arduino_mount1_1.stl" scale="0.001 0.001 0.001"/>
    </geometry>
  </collision>
</link>

<joint name="Rigid1" type="fixed">
  <origin rpy="0 0 0" xyz="0.0 0.0 0.139"/>
  <parent link="base_link"/>
  <child link="base_shell1_1"/>
</joint>

<joint name="Rigid2" type="fixed">
  <origin rpy="0 0 0" xyz="0.0 0.0 0.0"/>
  <parent link="base_shell1_1"/>
  <child link="base_shell2_1"/>
</joint>

<joint name="Rigid4" type="fixed">
  <origin rpy="0 0 0" xyz="0.059036 -0.01299 0.045"/>
  <parent link="base_shell2_1"/>
  <child link="base_plate2_1"/>
</joint>

<joint name="Rigid5" type="fixed">
  <origin rpy="0 0 0" xyz="0.059036 -0.01299 0.045"/>
  <parent link="base_shell3_1"/>
  <child link="base_plate2_1"/>
</joint>

<joint name="Rigid6" type="fixed">
  <origin rpy="0 0 0" xyz="-0.018268 0.057622 0.045"/>
  <parent link="base_shell3_1"/>
  <child link="base_plate3_1"/>
</joint>

<joint name="Rigid7" type="fixed">
  <origin rpy="0 0 0" xyz="-0.018268 0.057622 0.045"/>
  <parent link="base_shell1_1"/>
  <child link="base_plate3_1"/>
</joint>

<joint name="Rigid8" type="fixed">
  <origin rpy="0 0 0" xyz="-0.040768 -0.044631 0.045"/>
  <parent link="base_shell1_1"/>
  <child link="base_plate1_1"/>
</joint>

<joint name="Rigid9" type="fixed">
  <origin rpy="0 0 0" xyz="-0.040768 -0.044631 0.045"/>
  <parent link="base_shell2_1"/>
  <child link="base_plate1_1"/>
</joint>

<joint name="Rigid10" type="fixed">
  <origin rpy="0 0 0" xyz="0.016847 0.03082 0.003"/>
  <parent link="base_plate1_1"/>
  <child link="vertical_bay1_1"/>
</joint>

<joint name="Rigid11" type="fixed">
  <origin rpy="0 0 0" xyz="0.018268 -0.03 0.003"/>
  <parent link="base_plate3_1"/>
  <child link="vertical_bay3_1"/>
</joint>

<joint name="Rigid12" type="fixed">
  <origin rpy="0 0 0" xyz="-0.035115 -0.000821 0.003"/>
  <parent link="base_plate2_1"/>
  <child link="vertical_bay2_1"/>
</joint>

<joint name="Rigid15" type="fixed">
  <origin rpy="0 0 0" xyz="0.002598 -0.0015 0.0325"/>
  <parent link="vertical_bay2_1"/>
  <child link="arduino_mount2_1"/>
</joint>

<joint name="Rigid17" type="fixed">
  <origin rpy="0 0 0" xyz="-0.011899 -0.030609 -0.0085"/>
  <parent link="arduino_mount2_1"/>
  <child link="arduino2_1"/>
</joint>

<joint name="Rigid18" type="fixed">
  <origin rpy="0 0 0" xyz="-0.020559 0.02561 -0.0085"/>
  <parent link="arduino_mount1_1"/>
  <child link="arduino1_1"/>
</joint>

<joint name="Rigid20" type="fixed">
  <origin rpy="0 0 0" xyz="-0.001386 -0.0008 -0.0001"/>
  <parent link="arduino1_1"/>
  <child link="simplefocshield1_1"/>
</joint>

<joint name="Rigid21" type="fixed">
  <origin rpy="0 0 0" xyz="0.001386 -0.0008 -0.0001"/>
  <parent link="arduino2_1"/>
  <child link="simplefocshield2_1"/>
</joint>

<joint name="Rigid23" type="fixed">
  <origin rpy="0 0 0" xyz="0.064916 0.0016 -0.0169"/>
  <parent link="arduino3_1"/>
  <child link="simplefocshield3_1"/>
</joint>

<joint name="Rigid24" type="fixed">
  <origin rpy="0 0 0" xyz="-0.032458 0.005 0.0085"/>
  <parent link="arduino_mount3_1"/>
  <child link="arduino3_1"/>
</joint>

<joint name="Rigid25" type="fixed">
  <origin rpy="0 0 0" xyz="0.0 0.003 0.0325"/>
  <parent link="vertical_bay3_1"/>
  <child link="arduino_mount3_1"/>
</joint>

<joint name="Rigid26" type="fixed">
  <origin rpy="0 0 0" xyz="0.0 0.0 0.068"/>
  <parent link="vertical_bay1_1"/>
  <child link="top_plate_1"/>
</joint>

<joint name="Rigid27" type="fixed">
  <origin rpy="0 0 0" xyz="0.023921 0.003311 0.006"/>
  <parent link="top_plate_1"/>
  <child link="breadboard_1"/>
</joint>

<joint name="Rigid28" type="fixed">
  <origin rpy="0 0 0" xyz="0.000352 -0.016908 -0.006"/>
  <parent link="breadboard_1"/>
  <child link="arduino_nano_1"/>
</joint>

<joint name="Rigid29" type="fixed">
  <origin rpy="0 0 0" xyz="0.0 0.0039 0.292"/>
  <parent link="base_link"/>
  <child link="rasbperry_pi_1"/>
</joint>

<joint name="Rigid30" type="fixed">
  <origin rpy="0 0 0" xyz="-0.046487 0.026839 0.032056"/>
  <parent link="base_shell1_1"/>
  <child link="motor_mount1_1"/>
</joint>

<joint name="Rigid31" type="fixed">
  <origin rpy="0 0 0" xyz="0.0 -0.053678 0.032056"/>
  <parent link="base_shell2_1"/>
  <child link="motor_mount2_1"/>
</joint>

<joint name="Rigid32" type="fixed">
  <origin rpy="0 0 0" xyz="0.046487 0.026839 0.032056"/>
  <parent link="base_shell3_1"/>
  <child link="motor_mount3_1"/>
</joint>

<joint name="Rigid33" type="fixed">
  <origin rpy="0 0 0" xyz="0.0 -0.005657 -0.005657"/>
  <parent link="motor_mount2_1"/>
  <child link="motor_stator2_1"/>
</joint>

<joint name="Rigid34" type="fixed">
  <origin rpy="0 0 0" xyz="0.004899 0.002828 -0.005657"/>
  <parent link="motor_mount3_1"/>
  <child link="motor_stator3_1"/>
</joint>

<joint name="Rigid35" type="fixed">
  <origin rpy="0 0 0" xyz="-0.004899 0.002828 -0.005657"/>
  <parent link="motor_mount1_1"/>
  <child link="motor_stator1_1"/>
</joint>

<joint name="MotorJoint1" type="continuous">
  <origin rpy="0 0 0" xyz="0.009798 -0.005656 -0.016798"/>
  <parent link="motor_stator1_1"/>
  <child link="motor_rotor1_1"/>
  <axis xyz="-0.612372 0.353553 -0.707107"/>
</joint>

<joint name="MotorJoint2" type="continuous">
  <origin rpy="0 0 0" xyz="0.0 0.011314 -0.016798"/>
  <parent link="motor_stator2_1"/>
  <child link="motor_rotor2_1"/>
  <axis xyz="0.0 -0.707107 -0.707107"/>
</joint>

<joint name="MotorJoint3" type="continuous">
  <origin rpy="0 0 0" xyz="-0.009798 -0.005656 -0.016798"/>
  <parent link="motor_stator3_1"/>
  <child link="motor_rotor3_1"/>
  <axis xyz="0.612372 0.353553 -0.707107"/>
</joint>

<joint name="Rigid40" type="fixed">
  <origin rpy="0 0 0" xyz="0.011267 0.006505 -0.013011"/>
  <parent link="motor_rotor3_1"/>
  <child link="wheel_body3_1"/>
</joint>

<joint name="Rigid41" type="fixed">
  <origin rpy="0 0 0" xyz="0.0 -0.013011 -0.013011"/>
  <parent link="motor_rotor2_1"/>
  <child link="wheel_body2_1"/>
</joint>

<joint name="Rigid42" type="fixed">
  <origin rpy="0 0 0" xyz="-0.011267 0.006505 -0.013011"/>
  <parent link="motor_rotor1_1"/>
  <child link="wheel_body1_1"/>
</joint>

<joint name="Rev43" type="continuous">
  <origin rpy="0 0 0" xyz="0.011267 -0.006505 -0.032416"/>
  <parent link="wheel_body1_1"/>
  <child link="wheel_roller1.10_1"/>
  <axis xyz="-0.5 -0.866025 -0.0"/>
</joint>

<joint name="Rev44" type="continuous">
  <origin rpy="0 0 0" xyz="-0.028248 0.002704 0.00743"/>
  <parent link="wheel_body1_1"/>
  <child link="wheel_roller1.4_1"/>
  <axis xyz="-0.126826 -0.926777 -0.353553"/>
</joint>

<joint name="Rev45" type="continuous">
  <origin rpy="0 0 0" xyz="-0.02928 -0.013095 -0.000596"/>
  <parent link="wheel_body1_1"/>
  <child link="wheel_roller1.9_1"/>
  <axis xyz="0.28033 -0.739199 -0.612372"/>
</joint>

<joint name="Rev46" type="continuous">
  <origin rpy="0 0 0" xyz="0.000247 -0.015308 -0.027274"/>
  <parent link="wheel_body1_1"/>
  <child link="wheel_roller1.5_1"/>
  <axis xyz="0.739199 0.573223 -0.353553"/>
</joint>

<joint name="Rev47" type="continuous">
  <origin rpy="0 0 0" xyz="0.006021 0.026834 -0.011203"/>
  <parent link="wheel_body1_1"/>
  <child link="wheel_roller1.3_1"/>
  <axis xyz="0.612372 -0.353553 -0.707107"/>
</joint>

<joint name="Rev48" type="continuous">
  <origin rpy="0 0 0" xyz="0.01338 0.00743 -0.027277"/>
  <parent link="wheel_body1_1"/>
  <child link="wheel_roller1.6_1"/>
  <axis xyz="-0.126826 -0.926777 -0.353553"/>
</joint>

<joint name="Rev49" type="continuous">
  <origin rpy="0 0 0" xyz="-0.003299 0.031905 -0.000596"/>
  <parent link="wheel_body1_1"/>
  <child link="wheel_roller1.8_1"/>
  <axis xyz="0.78033 0.126826 -0.612372"/>
</joint>

<joint name="Rev50" type="continuous">
  <origin rpy="0 0 0" xyz="-0.020229 -0.018632 -0.011203"/>
  <parent link="wheel_body1_1"/>
  <child link="wheel_roller1.7_1"/>
  <axis xyz="0.612372 -0.353553 -0.707107"/>
</joint>

<joint name="Rev51" type="continuous">
  <origin rpy="0 0 0" xyz="-0.014462 0.023505 0.004872"/>
  <parent link="wheel_body1_1"/>
  <child link="wheel_roller1.1_1"/>
  <axis xyz="0.739199 0.573223 -0.353553"/>
</joint>

<joint name="Rev52" type="continuous">
  <origin rpy="0 0 0" xyz="-0.025475 0.014708 0.010011"/>
  <parent link="wheel_body1_1"/>
  <child link="wheel_roller1.2_1"/>
  <axis xyz="0.5 0.866025 0.0"/>
</joint>

<joint name="Rev53" type="continuous">
  <origin rpy="0 0 0" xyz="-0.010916 -0.023703 -0.021803"/>
  <parent link="wheel_body1_1"/>
  <child link="wheel_roller1.12_1"/>
  <axis xyz="-0.78033 -0.126826 0.612372"/>
</joint>

<joint name="Rev54" type="continuous">
  <origin rpy="0 0 0" xyz="0.015072 0.021298 -0.021809"/>
  <parent link="wheel_body1_1"/>
  <child link="wheel_roller1.11_1"/>
  <axis xyz="0.28033 -0.739199 -0.612372"/>
</joint>

<joint name="Rev55" type="continuous">
  <origin rpy="0 0 0" xyz="0.02625 -0.008202 -0.011203"/>
  <parent link="wheel_body2_1"/>
  <child link="wheel_roller2.12_1"/>
  <axis xyz="0.0 0.707107 -0.707107"/>
</joint>

<joint name="Rev56" type="continuous">
  <origin rpy="0 0 0" xyz="0.025986 0.002398 -0.021803"/>
  <parent link="wheel_body2_1"/>
  <child link="wheel_roller2.9_1"/>
  <axis xyz="0.5 -0.612372 0.612372"/>
</joint>

<joint name="Rev57" type="continuous">
  <origin rpy="0 0 0" xyz="-0.025981 0.002404 -0.021809"/>
  <parent link="wheel_body2_1"/>
  <child link="wheel_roller2.11_1"/>
  <axis xyz="0.5 0.612372 -0.612372"/>
</joint>

<joint name="Rev58" type="continuous">
  <origin rpy="0 0 0" xyz="-0.02625 -0.008202 -0.011203"/>
  <parent link="wheel_body2_1"/>
  <child link="wheel_roller2.3_1"/>
  <axis xyz="0.0 0.707107 -0.707107"/>
</joint>

<joint name="Rev59" type="continuous">
  <origin rpy="0 0 0" xyz="0.0 0.013011 -0.032416"/>
  <parent link="wheel_body2_1"/>
  <child link="wheel_roller2.10_1"/>
  <axis xyz="1.0 -0.0 -0.0"/>
</joint>

<joint name="Rev60" type="continuous">
  <origin rpy="0 0 0" xyz="0.013134 0.007869 -0.027274"/>
  <parent link="wheel_body2_1"/>
  <child link="wheel_roller2.5_1"/>
  <axis xyz="-0.866025 0.353553 -0.353553"/>
</joint>

<joint name="Rev61" type="continuous">
  <origin rpy="0 0 0" xyz="-0.013125 0.007872 -0.027277"/>
  <parent link="wheel_body2_1"/>
  <child link="wheel_roller2.6_1"/>
  <axis xyz="0.866025 0.353553 -0.353553"/>
</joint>

<joint name="Rev62" type="continuous">
  <origin rpy="0 0 0" xyz="0.0 -0.029416 0.010011"/>
  <parent link="wheel_body2_1"/>
  <child link="wheel_roller2.2_1"/>
  <axis xyz="-1.0 0.0 -0.0"/>
</joint>

<joint name="Rev63" type="continuous">
  <origin rpy="0 0 0" xyz="-0.013125 -0.024277 0.004872"/>
  <parent link="wheel_body2_1"/>
  <child link="wheel_roller2.1_1"/>
  <axis xyz="-0.866025 0.353553 -0.353553"/>
</joint>

<joint name="Rev64" type="continuous">
  <origin rpy="0 0 0" xyz="0.025981 -0.018809 -0.000596"/>
  <parent link="wheel_body2_1"/>
  <child link="wheel_roller2.7_1"/>
  <axis xyz="0.5 0.612372 -0.612372"/>
</joint>

<joint name="Rev65" type="continuous">
  <origin rpy="0 0 0" xyz="-0.025981 -0.018809 -0.000596"/>
  <parent link="wheel_body2_1"/>
  <child link="wheel_roller2.8_1"/>
  <axis xyz="-0.5 0.612372 -0.612372"/>
</joint>

<joint name="Rev66" type="continuous">
  <origin rpy="0 0 0" xyz="0.011783 -0.025815 0.00743"/>
  <parent link="wheel_body2_1"/>
  <child link="wheel_roller2.4_1"/>
  <axis xyz="0.866025 0.353553 -0.353553"/>
</joint>

<joint name="Rev67" type="continuous">
  <origin rpy="0 0 0" xyz="-0.015069 0.021305 -0.021803"/>
  <parent link="wheel_body3_1"/>
  <child link="wheel_roller3.12_1"/>
  <axis xyz="0.28033 0.739199 0.612372"/>
</joint>

<joint name="Rev68" type="continuous">
  <origin rpy="0 0 0" xyz="-0.011267 -0.006505 -0.032416"/>
  <parent link="wheel_body3_1"/>
  <child link="wheel_roller3.10_1"/>
  <axis xyz="-0.5 0.866025 0.0"/>
</joint>

<joint name="Rev69" type="continuous">
  <origin rpy="0 0 0" xyz="-0.000255 -0.015303 -0.027277"/>
  <parent link="wheel_body3_1"/>
  <child link="wheel_roller3.6_1"/>
  <axis xyz="-0.739199 0.573223 -0.353553"/>
</joint>

<joint name="Rev70" type="continuous">
  <origin rpy="0 0 0" xyz="-0.006021 0.026834 -0.011203"/>
  <parent link="wheel_body3_1"/>
  <child link="wheel_roller3.7_1"/>
  <axis xyz="-0.612372 -0.353553 -0.707107"/>
</joint>

<joint name="Rev71" type="continuous">
  <origin rpy="0 0 0" xyz="0.020229 -0.018632 -0.011203"/>
  <parent link="wheel_body3_1"/>
  <child link="wheel_roller3.3_1"/>
  <axis xyz="-0.612372 -0.353553 -0.707107"/>
</joint>

<joint name="Rev72" type="continuous">
  <origin rpy="0 0 0" xyz="0.027587 0.000772 0.004872"/>
  <parent link="wheel_body3_1"/>
  <child link="wheel_roller3.1_1"/>
  <axis xyz="0.126826 -0.926777 -0.353553"/>
</joint>

<joint name="Rev73" type="continuous">
  <origin rpy="0 0 0" xyz="0.010909 -0.023702 -0.021809"/>
  <parent link="wheel_body3_1"/>
  <child link="wheel_roller3.11_1"/>
  <axis xyz="-0.78033 0.126826 -0.612372"/>
</joint>

<joint name="Rev74" type="continuous">
  <origin rpy="0 0 0" xyz="0.02928 -0.013095 -0.000596"/>
  <parent link="wheel_body3_1"/>
  <child link="wheel_roller3.8_1"/>
  <axis xyz="-0.28033 -0.739199 -0.612372"/>
</joint>

<joint name="Rev75" type="continuous">
  <origin rpy="0 0 0" xyz="0.003299 0.031905 -0.000596"/>
  <parent link="wheel_body3_1"/>
  <child link="wheel_roller3.9_1"/>
  <axis xyz="-0.78033 0.126826 -0.612372"/>
</joint>

<joint name="Rev76" type="continuous">
  <origin rpy="0 0 0" xyz="0.025475 0.014708 0.010011"/>
  <parent link="wheel_body3_1"/>
  <child link="wheel_roller3.2_1"/>
  <axis xyz="0.5 -0.866025 -0.0"/>
</joint>

<joint name="Rev77" type="continuous">
  <origin rpy="0 0 0" xyz="-0.013381 0.00744 -0.027274"/>
  <parent link="wheel_body3_1"/>
  <child link="wheel_roller3.5_1"/>
  <axis xyz="0.126826 -0.926777 -0.353553"/>
</joint>

<joint name="Rev78" type="continuous">
  <origin rpy="0 0 0" xyz="0.016466 0.023112 0.00743"/>
  <parent link="wheel_body3_1"/>
  <child link="wheel_roller3.4_1"/>
  <axis xyz="-0.739199 0.573223 -0.353553"/>
</joint>

<joint name="Rigid3" type="fixed">
  <origin rpy="0 0 0" xyz="0.0 0.0 0.0"/>
  <parent link="base_shell1_1"/>
  <child link="base_shell3_1"/>
</joint>

<joint name="Rigid13" type="fixed">
  <origin rpy="0 0 0" xyz="-0.002598 -0.0015 0.0325"/>
  <parent link="vertical_bay1_1"/>
  <child link="arduino_mount1_1"/>
</joint>

</robot>
