<?xml version="1.0" ?>
<robot name="deep_ballbot" xmlns:xacro="http://www.ros.org/wiki/xacro">

<xacro:include filename="$(find deep_ballbot_description)/urdf/materials.xacro" />
<xacro:include filename="$(find deep_ballbot_description)/urdf/deep_ballbot.trans" />
<xacro:include filename="$(find deep_ballbot_description)/urdf/deep_ballbot.gazebo" />
<link name="base_link">
  <inertial>
    <origin rpy="0 0 0" xyz="1.2837111033282416e-16 -5.2625812969710457e-17 0.19100000000000006"/>
    <mass value="0.1429407"/>
    <inertia ixx="0.001077" ixy="-0.0" ixz="0.0" iyy="0.001077" iyz="0.0" izz="1.1e-05"/>
  </inertial>
  <visual>
    <origin rpy="0 0 0" xyz="0 0 0"/>
    <geometry>
      <mesh filename="package://deep_ballbot_description/meshes/base_link.stl" scale="0.001 0.001 0.001"/>
    </geometry>
    <material name="silver"/>
  </visual>
  <collision>
    <origin rpy="0 0 0" xyz="0 0 0"/>
    <geometry>
      <mesh filename="package://deep_ballbot_description/meshes/base_link.stl" scale="0.001 0.001 0.001"/>
    </geometry>
  </collision>
</link>

<link name="base_shell1_1">
  <inertial>
    <origin rpy="0 0 0" xyz="-0.031549302946108734 0.018214998548683036 0.021364464404157207"/>
    <mass value="0.03897424370875784"/>
    <inertia ixx="3.3e-05" ixy="-1.1e-05" ixz="6e-06" iyy="2e-05" iyz="-3e-06" izz="3.8e-05"/>
  </inertial>
  <visual>
    <origin rpy="0 0 0" xyz="-0.0 -0.0 -0.041"/>
    <geometry>
      <mesh filename="package://deep_ballbot_description/meshes/base_shell1_1.stl" scale="0.001 0.001 0.001"/>
    </geometry>
    <material name="silver"/>
  </visual>
  <collision>
    <origin rpy="0 0 0" xyz="-0.0 -0.0 -0.041"/>
    <geometry>
      <mesh filename="package://deep_ballbot_description/meshes/base_shell1_1.stl" scale="0.001 0.001 0.001"/>
    </geometry>
  </collision>
</link>

<link name="base_shell2_1">
  <inertial>
    <origin rpy="0 0 0" xyz="-3.3934854264068832e-15 -0.03702245966743248 0.022039444136548507"/>
    <mass value="0.037632056653399956"/>
    <inertia ixx="1.3e-05" ixy="-0.0" ixz="-0.0" iyy="3.8e-05" iyz="6e-06" izz="3.7e-05"/>
  </inertial>
  <visual>
    <origin rpy="0 0 0" xyz="-0.0 -0.0 -0.041"/>
    <geometry>
      <mesh filename="package://deep_ballbot_description/meshes/base_shell2_1.stl" scale="0.001 0.001 0.001"/>
    </geometry>
    <material name="silver"/>
  </visual>
  <collision>
    <origin rpy="0 0 0" xyz="-0.0 -0.0 -0.041"/>
    <geometry>
      <mesh filename="package://deep_ballbot_description/meshes/base_shell2_1.stl" scale="0.001 0.001 0.001"/>
    </geometry>
  </collision>
</link>

<link name="base_shell3_1">
  <inertial>
    <origin rpy="0 0 0" xyz="0.031549302946108124 0.01821499854867945 0.021364464404157207"/>
    <mass value="0.03897424370875779"/>
    <inertia ixx="3.3e-05" ixy="1.1e-05" ixz="-6e-06" iyy="2e-05" iyz="-3e-06" izz="3.8e-05"/>
  </inertial>
  <visual>
    <origin rpy="0 0 0" xyz="-0.0 -0.0 -0.041"/>
    <geometry>
      <mesh filename="package://deep_ballbot_description/meshes/base_shell3_1.stl" scale="0.001 0.001 0.001"/>
    </geometry>
    <material name="silver"/>
  </visual>
  <collision>
    <origin rpy="0 0 0" xyz="-0.0 -0.0 -0.041"/>
    <geometry>
      <mesh filename="package://deep_ballbot_description/meshes/base_shell3_1.stl" scale="0.001 0.001 0.001"/>
    </geometry>
  </collision>
</link>

<link name="base_plate2_1">
  <inertial>
    <origin rpy="0 0 0" xyz="-0.008447575075313303 0.025970793969406256 0.0029137797806522286"/>
    <mass value="0.029331775102842923"/>
    <inertia ixx="1.5e-05" ixy="-6e-06" ixz="-0.0" iyy="9e-06" iyz="0.0" izz="2.4e-05"/>
  </inertial>
  <visual>
    <origin rpy="0 0 0" xyz="-0.040768 0.044631 -0.086"/>
    <geometry>
      <mesh filename="package://deep_ballbot_description/meshes/base_plate2_1.stl" scale="0.001 0.001 0.001"/>
    </geometry>
    <material name="silver"/>
  </visual>
  <collision>
    <origin rpy="0 0 0" xyz="-0.040768 0.044631 -0.086"/>
    <geometry>
      <mesh filename="package://deep_ballbot_description/meshes/base_plate2_1.stl" scale="0.001 0.001 0.001"/>
    </geometry>
  </collision>
</link>

<link name="base_plate3_1">
  <inertial>
    <origin rpy="0 0 0" xyz="-0.018267999999997068 -0.020301587938816257 0.002913779780652437"/>
    <mass value="0.029331775102842902"/>
    <inertia ixx="5e-06" ixy="-0.0" ixz="0.0" iyy="1.9e-05" iyz="-0.0" izz="2.4e-05"/>
  </inertial>
  <visual>
    <origin rpy="0 0 0" xyz="-0.018268 -0.057622 -0.086"/>
    <geometry>
      <mesh filename="package://deep_ballbot_description/meshes/base_plate3_1.stl" scale="0.001 0.001 0.001"/>
    </geometry>
    <material name="silver"/>
  </visual>
  <collision>
    <origin rpy="0 0 0" xyz="-0.018268 -0.057622 -0.086"/>
    <geometry>
      <mesh filename="package://deep_ballbot_description/meshes/base_plate3_1.stl" scale="0.001 0.001 0.001"/>
    </geometry>
  </collision>
</link>

<link name="vertical_bay1_1">
  <inertial>
    <origin rpy="0 0 0" xyz="-1.616755785013857e-07 1.108667959468651e-07 0.034267969497609505"/>
    <mass value="0.02673500652833671"/>
    <inertia ixx="1.7e-05" ixy="4e-06" ixz="0.0" iyy="1.3e-05" iyz="0.0" izz="8e-06"/>
  </inertial>
  <visual>
    <origin rpy="0 0 0" xyz="0.023921 0.013811 -0.089"/>
    <geometry>
      <mesh filename="package://deep_ballbot_description/meshes/vertical_bay1_1.stl" scale="0.001 0.001 0.001"/>
    </geometry>
    <material name="silver"/>
  </visual>
  <collision>
    <origin rpy="0 0 0" xyz="0.023921 0.013811 -0.089"/>
    <geometry>
      <mesh filename="package://deep_ballbot_description/meshes/vertical_bay1_1.stl" scale="0.001 0.001 0.001"/>
    </geometry>
  </collision>
</link>

<link name="vertical_bay2_1">
  <inertial>
    <origin rpy="0 0 0" xyz="1.6167524614571493e-07 1.1086746289426519e-07 0.034307521329889665"/>
    <mass value="0.026769047843990496"/>
    <inertia ixx="1.8e-05" ixy="-4e-06" ixz="0.0" iyy="1.3e-05" iyz="-0.0" izz="8e-06"/>
  </inertial>
  <visual>
    <origin rpy="0 0 0" xyz="-0.023921 0.013811 -0.089"/>
    <geometry>
      <mesh filename="package://deep_ballbot_description/meshes/vertical_bay2_1.stl" scale="0.001 0.001 0.001"/>
    </geometry>
    <material name="silver"/>
  </visual>
  <collision>
    <origin rpy="0 0 0" xyz="-0.023921 0.013811 -0.089"/>
    <geometry>
      <mesh filename="package://deep_ballbot_description/meshes/vertical_bay2_1.stl" scale="0.001 0.001 0.001"/>
    </geometry>
  </collision>
</link>

<link name="vertical_bay3_1">
  <inertial>
    <origin rpy="0 0 0" xyz="4.882478034425914e-15 -2.217349333276386e-07 0.03430752132988979"/>
    <mass value="0.026769047843990493"/>
    <inertia ixx="1.1e-05" ixy="-0.0" ixz="-0.0" iyy="2e-05" iyz="0.0" izz="8e-06"/>
  </inertial>
  <visual>
    <origin rpy="0 0 0" xyz="-0.0 -0.027622 -0.089"/>
    <geometry>
      <mesh filename="package://deep_ballbot_description/meshes/vertical_bay3_1.stl" scale="0.001 0.001 0.001"/>
    </geometry>
    <material name="silver"/>
  </visual>
  <collision>
    <origin rpy="0 0 0" xyz="-0.0 -0.027622 -0.089"/>
    <geometry>
      <mesh filename="package://deep_ballbot_description/meshes/vertical_bay3_1.stl" scale="0.001 0.001 0.001"/>
    </geometry>
  </collision>
</link>

<link name="breadboard_1">
  <inertial>
    <origin rpy="0 0 0" xyz="-3.5127803936496616e-10 0.017499602320883708 0.00399999999999992"/>
    <mass value="0.016254000000000088"/>
    <inertia ixx="2e-06" ixy="-0.0" ixz="-0.0" iyy="3e-06" iyz="0.0" izz="4e-06"/>
  </inertial>
  <visual>
    <origin rpy="0 0 0" xyz="0.0 0.047631 -0.16"/>
    <geometry>
      <mesh filename="package://deep_ballbot_description/meshes/breadboard_1.stl" scale="0.001 0.001 0.001"/>
    </geometry>
    <material name="silver"/>
  </visual>
  <collision>
    <origin rpy="0 0 0" xyz="0.0 0.047631 -0.16"/>
    <geometry>
      <mesh filename="package://deep_ballbot_description/meshes/breadboard_1.stl" scale="0.001 0.001 0.001"/>
    </geometry>
  </collision>
</link>

<link name="arduino_nano_1">
  <inertial>
    <origin rpy="0 0 0" xyz="-0.0015922703223249027 0.001539602311244493 -0.08364411659311086"/>
    <mass value="0.014605507737955568"/>
    <inertia ixx="1e-06" ixy="-0.0" ixz="0.0" iyy="2e-06" iyz="0.0" izz="3e-06"/>
  </inertial>
  <visual>
    <origin rpy="0 0 0" xyz="-0.000352 0.031671 -0.255"/>
    <geometry>
      <mesh filename="package://deep_ballbot_description/meshes/arduino_nano_1.stl" scale="0.001 0.001 0.001"/>
    </geometry>
    <material name="silver"/>
  </visual>
  <collision>
    <origin rpy="0 0 0" xyz="-0.000352 0.031671 -0.255"/>
    <geometry>
      <mesh filename="package://deep_ballbot_description/meshes/arduino_nano_1.stl" scale="0.001 0.001 0.001"/>
    </geometry>
  </collision>
</link>

<link name="rasbperry_pi_1">
  <inertial>
    <origin rpy="0 0 0" xyz="-0.0012540090701389367 0.004888830200197092 0.057465472519733246"/>
    <mass value="0.13472167579144456"/>
    <inertia ixx="8.3e-05" ixy="0.0" ixz="-0.0" iyy="0.000118" iyz="-9e-06" izz="4.1e-05"/>
  </inertial>
  <visual>
    <origin rpy="0 0 0" xyz="0.0 -0.0105 -0.16"/>
    <geometry>
      <mesh filename="package://deep_ballbot_description/meshes/rasbperry_pi_1.stl" scale="0.001 0.001 0.001"/>
    </geometry>
    <material name="silver"/>
  </visual>
  <collision>
    <origin rpy="0 0 0" xyz="0.0 -0.0105 -0.16"/>
    <geometry>
      <mesh filename="package://deep_ballbot_description/meshes/rasbperry_pi_1.stl" scale="0.001 0.001 0.001"/>
    </geometry>
  </collision>
</link>

<link name="motor_mount1_1">
  <inertial>
    <origin rpy="0 0 0" xyz="0.008784093083896244 -0.005071216542772327 -0.01575982915390229"/>
    <mass value="0.08608420182582005"/>
    <inertia ixx="3.8e-05" ixy="-9e-06" ixz="1e-05" iyy="2.8e-05" iyz="-6e-06" izz="4.3e-05"/>
  </inertial>
  <visual>
    <origin rpy="0 0 0" xyz="0.046487 -0.026839 -0.073056"/>
    <geometry>
      <mesh filename="package://deep_ballbot_description/meshes/motor_mount1_1.stl" scale="0.001 0.001 0.001"/>
    </geometry>
    <material name="silver"/>
  </visual>
  <collision>
    <origin rpy="0 0 0" xyz="0.046487 -0.026839 -0.073056"/>
    <geometry>
      <mesh filename="package://deep_ballbot_description/meshes/motor_mount1_1.stl" scale="0.001 0.001 0.001"/>
    </geometry>
  </collision>
</link>

<link name="motor_mount2_1">
  <inertial>
    <origin rpy="0 0 0" xyz="1.2782595203488562e-14 0.01014243308566861 -0.015759829153752188"/>
    <mass value="0.08608420182581958"/>
    <inertia ixx="2.3e-05" ixy="0.0" ixz="-0.0" iyy="4.3e-05" iyz="1.1e-05" izz="4.3e-05"/>
  </inertial>
  <visual>
    <origin rpy="0 0 0" xyz="-0.0 0.053678 -0.073056"/>
    <geometry>
      <mesh filename="package://deep_ballbot_description/meshes/motor_mount2_1.stl" scale="0.001 0.001 0.001"/>
    </geometry>
    <material name="silver"/>
  </visual>
  <collision>
    <origin rpy="0 0 0" xyz="-0.0 0.053678 -0.073056"/>
    <geometry>
      <mesh filename="package://deep_ballbot_description/meshes/motor_mount2_1.stl" scale="0.001 0.001 0.001"/>
    </geometry>
  </collision>
</link>

<link name="motor_mount3_1">
  <inertial>
    <origin rpy="0 0 0" xyz="-0.008784093083910455 -0.0050712165427470035 -0.015759829153901964"/>
    <mass value="0.08608420182581962"/>
    <inertia ixx="3.8e-05" ixy="9e-06" ixz="-1e-05" iyy="2.8e-05" iyz="-6e-06" izz="4.3e-05"/>
  </inertial>
  <visual>
    <origin rpy="0 0 0" xyz="-0.046487 -0.026839 -0.073056"/>
    <geometry>
      <mesh filename="package://deep_ballbot_description/meshes/motor_mount3_1.stl" scale="0.001 0.001 0.001"/>
    </geometry>
    <material name="silver"/>
  </visual>
  <collision>
    <origin rpy="0 0 0" xyz="-0.046487 -0.026839 -0.073056"/>
    <geometry>
      <mesh filename="package://deep_ballbot_description/meshes/motor_mount3_1.stl" scale="0.001 0.001 0.001"/>
    </geometry>
  </collision>
</link>

<link name="arduino_mount1_1">
  <inertial>
    <origin rpy="0 0 0" xyz="-0.0017985403607221756 -0.0017781689855501989 -2.161566186426045e-05"/>
    <mass value="0.023201510107992093"/>
    <inertia ixx="1.3e-05" ixy="5e-06" ixz="-0.0" iyy="8e-06" iyz="0.0" izz="1.2e-05"/>
  </inertial>
  <visual>
    <origin rpy="0 0 0" xyz="0.026519 0.015311 -0.1215"/>
    <geometry>
      <mesh filename="package://deep_ballbot_description/meshes/arduino_mount1_1.stl" scale="0.001 0.001 0.001"/>
    </geometry>
    <material name="silver"/>
  </visual>
  <collision>
    <origin rpy="0 0 0" xyz="0.026519 0.015311 -0.1215"/>
    <geometry>
      <mesh filename="package://deep_ballbot_description/meshes/arduino_mount1_1.stl" scale="0.001 0.001 0.001"/>
    </geometry>
  </collision>
</link>

<link name="arduino_mount2_1">
  <inertial>
    <origin rpy="0 0 0" xyz="0.002439424651872954 -0.0006681248315035439 -2.1615661864302083e-05"/>
    <mass value="0.023201510107960607"/>
    <inertia ixx="1.3e-05" ixy="-5e-06" ixz="-0.0" iyy="8e-06" iyz="-0.0" izz="1.2e-05"/>
  </inertial>
  <visual>
    <origin rpy="0 0 0" xyz="-0.026519 0.015311 -0.1215"/>
    <geometry>
      <mesh filename="package://deep_ballbot_description/meshes/arduino_mount2_1.stl" scale="0.001 0.001 0.001"/>
    </geometry>
    <material name="silver"/>
  </visual>
  <collision>
    <origin rpy="0 0 0" xyz="-0.026519 0.015311 -0.1215"/>
    <geometry>
      <mesh filename="package://deep_ballbot_description/meshes/arduino_mount2_1.stl" scale="0.001 0.001 0.001"/>
    </geometry>
  </collision>
</link>

<link name="arduino_mount3_1">
  <inertial>
    <origin rpy="0 0 0" xyz="-0.0006408842911584954 0.0024462938179587064 -2.161566186449637e-05"/>
    <mass value="0.023201510107976293"/>
    <inertia ixx="5e-06" ixy="0.0" ixz="0.0" iyy="1.6e-05" iyz="0.0" izz="1.2e-05"/>
  </inertial>
  <visual>
    <origin rpy="0 0 0" xyz="-0.0 -0.030622 -0.1215"/>
    <geometry>
      <mesh filename="package://deep_ballbot_description/meshes/arduino_mount3_1.stl" scale="0.001 0.001 0.001"/>
    </geometry>
    <material name="silver"/>
  </visual>
  <collision>
    <origin rpy="0 0 0" xyz="-0.0 -0.030622 -0.1215"/>
    <geometry>
      <mesh filename="package://deep_ballbot_description/meshes/arduino_mount3_1.stl" scale="0.001 0.001 0.001"/>
    </geometry>
  </collision>
</link>

<link name="arduino1_1">
  <inertial>
    <origin rpy="0 0 0" xyz="0.016669585365093192 -0.03466135538645002 0.008758533737846977"/>
    <mass value="0.0763619336554754"/>
    <inertia ixx="4.9e-05" ixy="1.4e-05" ixz="0.0" iyy="2.9e-05" iyz="-1e-06" izz="3.5e-05"/>
  </inertial>
  <visual>
    <origin rpy="0 0 0" xyz="0.047078 -0.010299 -0.113"/>
    <geometry>
      <mesh filename="package://deep_ballbot_description/meshes/arduino1_1.stl" scale="0.001 0.001 0.001"/>
    </geometry>
    <material name="silver"/>
  </visual>
  <collision>
    <origin rpy="0 0 0" xyz="0.047078 -0.010299 -0.113"/>
    <geometry>
      <mesh filename="package://deep_ballbot_description/meshes/arduino1_1.stl" scale="0.001 0.001 0.001"/>
    </geometry>
  </collision>
</link>

<link name="arduino2_1">
  <inertial>
    <origin rpy="0 0 0" xyz="0.021682625979238333 0.0317667181299532 0.008758533737850557"/>
    <mass value="0.07636193365547596"/>
    <inertia ixx="4.6e-05" ixy="-1.6e-05" ixz="1e-06" iyy="3.2e-05" iyz="1e-06" izz="3.5e-05"/>
  </inertial>
  <visual>
    <origin rpy="0 0 0" xyz="-0.01462 0.04592 -0.113"/>
    <geometry>
      <mesh filename="package://deep_ballbot_description/meshes/arduino2_1.stl" scale="0.001 0.001 0.001"/>
    </geometry>
    <material name="silver"/>
  </visual>
  <collision>
    <origin rpy="0 0 0" xyz="-0.01462 0.04592 -0.113"/>
    <geometry>
      <mesh filename="package://deep_ballbot_description/meshes/arduino2_1.stl" scale="0.001 0.001 0.001"/>
    </geometry>
  </collision>
</link>

<link name="arduino3_1">
  <inertial>
    <origin rpy="0 0 0" xyz="-0.03835221134344279 0.0028936372564974805 0.008758533737797974"/>
    <mass value="0.07636193365547513"/>
    <inertia ixx="2.2e-05" ixy="2e-06" ixz="-1e-06" iyy="5.6e-05" iyz="0.0" izz="3.5e-05"/>
  </inertial>
  <visual>
    <origin rpy="0 0 0" xyz="-0.032458 -0.035622 -0.113"/>
    <geometry>
      <mesh filename="package://deep_ballbot_description/meshes/arduino3_1.stl" scale="0.001 0.001 0.001"/>
    </geometry>
    <material name="silver"/>
  </visual>
  <collision>
    <origin rpy="0 0 0" xyz="-0.032458 -0.035622 -0.113"/>
    <geometry>
      <mesh filename="package://deep_ballbot_description/meshes/arduino3_1.stl" scale="0.001 0.001 0.001"/>
    </geometry>
  </collision>
</link>

<link name="motor_stator1_1">
  <inertial>
    <origin rpy="0 0 0" xyz="0.013066369938678067 -0.00754315126884815 -0.016105881234575264"/>
    <mass value="0.2071891794839974"/>
    <inertia ixx="5.6e-05" ixy="-8e-06" ixz="1.6e-05" iyy="4.7e-05" iyz="-9e-06" izz="6.1e-05"/>
  </inertial>
  <visual>
    <origin rpy="0 0 0" xyz="0.051386 -0.029667 -0.067399"/>
    <geometry>
      <mesh filename="package://deep_ballbot_description/meshes/motor_stator1_1.stl" scale="0.001 0.001 0.001"/>
    </geometry>
    <material name="silver"/>
  </visual>
  <collision>
    <origin rpy="0 0 0" xyz="0.051386 -0.029667 -0.067399"/>
    <geometry>
      <mesh filename="package://deep_ballbot_description/meshes/motor_stator1_1.stl" scale="0.001 0.001 0.001"/>
    </geometry>
  </collision>
</link>

<link name="motor_stator2_1">
  <inertial>
    <origin rpy="0 0 0" xyz="5.843728574056933e-17 0.015087302537697661 -0.016105881234575015"/>
    <mass value="0.20718917948399745"/>
    <inertia ixx="4.2e-05" ixy="0.0" ixz="-0.0" iyy="6.1e-05" iyz="1.8e-05" izz="6.1e-05"/>
  </inertial>
  <visual>
    <origin rpy="0 0 0" xyz="-0.0 0.059335 -0.067399"/>
    <geometry>
      <mesh filename="package://deep_ballbot_description/meshes/motor_stator2_1.stl" scale="0.001 0.001 0.001"/>
    </geometry>
    <material name="silver"/>
  </visual>
  <collision>
    <origin rpy="0 0 0" xyz="-0.0 0.059335 -0.067399"/>
    <geometry>
      <mesh filename="package://deep_ballbot_description/meshes/motor_stator2_1.stl" scale="0.001 0.001 0.001"/>
    </geometry>
  </collision>
</link>

<link name="motor_stator3_1">
  <inertial>
    <origin rpy="0 0 0" xyz="-0.013066369938677755 -0.0075431512688483235 -0.01610588123457523"/>
    <mass value="0.2071891794839975"/>
    <inertia ixx="5.6e-05" ixy="8e-06" ixz="-1.6e-05" iyy="4.7e-05" iyz="-9e-06" izz="6.1e-05"/>
  </inertial>
  <visual>
    <origin rpy="0 0 0" xyz="-0.051386 -0.029667 -0.067399"/>
    <geometry>
      <mesh filename="package://deep_ballbot_description/meshes/motor_stator3_1.stl" scale="0.001 0.001 0.001"/>
    </geometry>
    <material name="silver"/>
  </visual>
  <collision>
    <origin rpy="0 0 0" xyz="-0.051386 -0.029667 -0.067399"/>
    <geometry>
      <mesh filename="package://deep_ballbot_description/meshes/motor_stator3_1.stl" scale="0.001 0.001 0.001"/>
    </geometry>
  </collision>
</link>

<link name="motor_rotor1_1">
  <inertial>
    <origin rpy="0 0 0" xyz="-0.0057593607274422295 0.0033250114622919713 0.08834875534169045"/>
    <mass value="0.37818287206036283"/>
    <inertia ixx="0.000136" ixy="-1.9e-05" ixz="3.7e-05" iyy="0.000115" iyz="-2.1e-05" izz="0.000147"/>
  </inertial>
  <visual>
    <origin rpy="0 0 0" xyz="0.041588 -0.024011 0.047399"/>
    <geometry>
      <mesh filename="package://deep_ballbot_description/meshes/motor_rotor1_1.stl" scale="0.001 0.001 0.001"/>
    </geometry>
    <material name="silver"/>
  </visual>
  <collision>
    <origin rpy="0 0 0" xyz="0.041588 -0.024011 0.047399"/>
    <geometry>
      <mesh filename="package://deep_ballbot_description/meshes/motor_rotor1_1.stl" scale="0.001 0.001 0.001"/>
    </geometry>
  </collision>
</link>

<link name="motor_rotor2_1">
  <inertial>
    <origin rpy="0 0 0" xyz="-7.656155528131342e-13 -0.006651022923255888 0.0883487553416902"/>
    <mass value="0.37818287206036244"/>
    <inertia ixx="0.000104" ixy="-0.0" ixz="-0.0" iyy="0.000147" iyz="4.3e-05" izz="0.000147"/>
  </inertial>
  <visual>
    <origin rpy="0 0 0" xyz="-0.0 0.048021 0.047399"/>
    <geometry>
      <mesh filename="package://deep_ballbot_description/meshes/motor_rotor2_1.stl" scale="0.001 0.001 0.001"/>
    </geometry>
    <material name="silver"/>
  </visual>
  <collision>
    <origin rpy="0 0 0" xyz="-0.0 0.048021 0.047399"/>
    <geometry>
      <mesh filename="package://deep_ballbot_description/meshes/motor_rotor2_1.stl" scale="0.001 0.001 0.001"/>
    </geometry>
  </collision>
</link>

<link name="motor_rotor3_1">
  <inertial>
    <origin rpy="0 0 0" xyz="0.005759360728208193 0.0033250114609655844 0.08834875534169054"/>
    <mass value="0.37818287206036283"/>
    <inertia ixx="0.000136" ixy="1.9e-05" ixz="-3.7e-05" iyy="0.000115" iyz="-2.1e-05" izz="0.000147"/>
  </inertial>
  <visual>
    <origin rpy="0 0 0" xyz="-0.041588 -0.024011 0.047399"/>
    <geometry>
      <mesh filename="package://deep_ballbot_description/meshes/motor_rotor3_1.stl" scale="0.001 0.001 0.001"/>
    </geometry>
    <material name="silver"/>
  </visual>
  <collision>
    <origin rpy="0 0 0" xyz="-0.041588 -0.024011 0.047399"/>
    <geometry>
      <mesh filename="package://deep_ballbot_description/meshes/motor_rotor3_1.stl" scale="0.001 0.001 0.001"/>
    </geometry>
  </collision>
</link>

<link name="wheel_body1_1">
  <inertial>
    <origin rpy="0 0 0" xyz="-0.006985828103879023 0.004056926498152404 0.08688646800127107"/>
    <mass value="0.01711866246905899"/>
    <inertia ixx="4e-06" ixy="-1e-06" ixz="1e-06" iyy="4e-06" iyz="-1e-06" izz="5e-06"/>
  </inertial>
  <visual>
    <origin rpy="0 0 0" xyz="0.052855 -0.030516 0.06041"/>
    <geometry>
      <mesh filename="package://deep_ballbot_description/meshes/wheel_body1_1.stl" scale="0.001 0.001 0.001"/>
    </geometry>
    <material name="silver"/>
  </visual>
  <collision>
    <origin rpy="0 0 0" xyz="0.052855 -0.030516 0.06041"/>
    <geometry>
      <mesh filename="package://deep_ballbot_description/meshes/wheel_body1_1.stl" scale="0.001 0.001 0.001"/>
    </geometry>
  </collision>
</link>

<link name="wheel_body2_1">
  <inertial>
    <origin rpy="0 0 0" xyz="-2.061845722735903e-05 -0.008078140713205603 0.08688646827764517"/>
    <mass value="0.01711866259314613"/>
    <inertia ixx="3e-06" ixy="-0.0" ixz="0.0" iyy="5e-06" iyz="2e-06" izz="5e-06"/>
  </inertial>
  <visual>
    <origin rpy="0 0 0" xyz="-0.0 0.061032 0.06041"/>
    <geometry>
      <mesh filename="package://deep_ballbot_description/meshes/wheel_body2_1.stl" scale="0.001 0.001 0.001"/>
    </geometry>
    <material name="silver"/>
  </visual>
  <collision>
    <origin rpy="0 0 0" xyz="-0.0 0.061032 0.06041"/>
    <geometry>
      <mesh filename="package://deep_ballbot_description/meshes/wheel_body2_1.stl" scale="0.001 0.001 0.001"/>
    </geometry>
  </collision>
</link>

<link name="wheel_body3_1">
  <inertial>
    <origin rpy="0 0 0" xyz="0.007006872776695483 0.0040212833613205295 0.08688695303756118"/>
    <mass value="0.017119124264976984"/>
    <inertia ixx="4e-06" ixy="1e-06" ixz="-1e-06" iyy="4e-06" iyz="-1e-06" izz="5e-06"/>
  </inertial>
  <visual>
    <origin rpy="0 0 0" xyz="-0.052855 -0.030516 0.06041"/>
    <geometry>
      <mesh filename="package://deep_ballbot_description/meshes/wheel_body3_1.stl" scale="0.001 0.001 0.001"/>
    </geometry>
    <material name="silver"/>
  </visual>
  <collision>
    <origin rpy="0 0 0" xyz="-0.052855 -0.030516 0.06041"/>
    <geometry>
      <mesh filename="package://deep_ballbot_description/meshes/wheel_body3_1.stl" scale="0.001 0.001 0.001"/>
    </geometry>
  </collision>
</link>

<link name="wheel_roller1_2_1">
  <inertial>
    <origin rpy="0 0 0" xyz="1.1343589692569545e-08 -1.599636007196259e-07 -4.949366527867705e-07"/>
    <mass value="0.0012011377071081658"/>
    <inertia ixx="0.0" ixy="-0.0" ixz="0.0" iyy="0.0" iyz="-0.0" izz="0.0"/>
  </inertial>
  <visual>
    <origin rpy="0 0 0" xyz="0.07833 -0.045224 -0.047601"/>
    <geometry>
      <mesh filename="package://deep_ballbot_description/meshes/wheel_roller1_2_1.stl" scale="0.001 0.001 0.001"/>
    </geometry>
    <material name="silver"/>
  </visual>
  <collision>
    <origin rpy="0 0 0" xyz="0.07833 -0.045224 -0.047601"/>
    <geometry>
      <mesh filename="package://deep_ballbot_description/meshes/wheel_roller1_2_1.stl" scale="0.001 0.001 0.001"/>
    </geometry>
  </collision>
</link>

<link name="wheel_roller1_4_1">
  <inertial>
    <origin rpy="0 0 0" xyz="0.0006668609842473833 -0.0018856180530571684 0.09545975573482343"/>
    <mass value="0.0025623256301060106"/>
    <inertia ixx="0.0" ixy="0.0" ixz="0.0" iyy="0.0" iyz="0.0" izz="0.0"/>
  </inertial>
  <visual>
    <origin rpy="0 0 0" xyz="0.081103 -0.03322 0.05298"/>
    <geometry>
      <mesh filename="package://deep_ballbot_description/meshes/wheel_roller1_4_1.stl" scale="0.001 0.001 0.001"/>
    </geometry>
    <material name="silver"/>
  </visual>
  <collision>
    <origin rpy="0 0 0" xyz="0.081103 -0.03322 0.05298"/>
    <geometry>
      <mesh filename="package://deep_ballbot_description/meshes/wheel_roller1_4_1.stl" scale="0.001 0.001 0.001"/>
    </geometry>
  </collision>
</link>

<link name="wheel_roller1_9_1">
  <inertial>
    <origin rpy="0 0 0" xyz="2.168223534465552e-07 -4.608225917974995e-07 -9.665432675748376e-08"/>
    <mass value="0.0012011377071081259"/>
    <inertia ixx="0.0" ixy="0.0" ixz="0.0" iyy="0.0" iyz="-0.0" izz="0.0"/>
  </inertial>
  <visual>
    <origin rpy="0 0 0" xyz="0.082135 -0.017421 -0.036994"/>
    <geometry>
      <mesh filename="package://deep_ballbot_description/meshes/wheel_roller1_9_1.stl" scale="0.001 0.001 0.001"/>
    </geometry>
    <material name="silver"/>
  </visual>
  <collision>
    <origin rpy="0 0 0" xyz="0.082135 -0.017421 -0.036994"/>
    <geometry>
      <mesh filename="package://deep_ballbot_description/meshes/wheel_roller1_9_1.stl" scale="0.001 0.001 0.001"/>
    </geometry>
  </collision>
</link>

<link name="wheel_roller1_7_1">
  <inertial>
    <origin rpy="0 0 0" xyz="1.84414555320922e-07 7.146925412593319e-08 3.016277919168364e-07"/>
    <mass value="0.0025623256301059846"/>
    <inertia ixx="0.0" ixy="-0.0" ixz="-0.0" iyy="0.0" iyz="0.0" izz="0.0"/>
  </inertial>
  <visual>
    <origin rpy="0 0 0" xyz="0.073084 -0.011884 -0.026387"/>
    <geometry>
      <mesh filename="package://deep_ballbot_description/meshes/wheel_roller1_7_1.stl" scale="0.001 0.001 0.001"/>
    </geometry>
    <material name="silver"/>
  </visual>
  <collision>
    <origin rpy="0 0 0" xyz="0.073084 -0.011884 -0.026387"/>
    <geometry>
      <mesh filename="package://deep_ballbot_description/meshes/wheel_roller1_7_1.stl" scale="0.001 0.001 0.001"/>
    </geometry>
  </collision>
</link>

<link name="wheel_roller1_12_1">
  <inertial>
    <origin rpy="0 0 0" xyz="-4.134077117995405e-07 -3.308052070258305e-07 -1.7636573396845323e-07"/>
    <mass value="0.0012011377071081525"/>
    <inertia ixx="0.0" ixy="-0.0" ixz="0.0" iyy="0.0" iyz="0.0" izz="0.0"/>
  </inertial>
  <visual>
    <origin rpy="0 0 0" xyz="0.063771 -0.006813 -0.015787"/>
    <geometry>
      <mesh filename="package://deep_ballbot_description/meshes/wheel_roller1_12_1.stl" scale="0.001 0.001 0.001"/>
    </geometry>
    <material name="silver"/>
  </visual>
  <collision>
    <origin rpy="0 0 0" xyz="0.063771 -0.006813 -0.015787"/>
    <geometry>
      <mesh filename="package://deep_ballbot_description/meshes/wheel_roller1_12_1.stl" scale="0.001 0.001 0.001"/>
    </geometry>
  </collision>
</link>

<link name="wheel_roller1_5_1">
  <inertial>
    <origin rpy="0 0 0" xyz="4.5717992872701396e-07 -4.655576233882769e-07 6.072471998158635e-08"/>
    <mass value="0.0025623256301060215"/>
    <inertia ixx="0.0" ixy="0.0" ixz="-0.0" iyy="0.0" iyz="-0.0" izz="0.0"/>
  </inertial>
  <visual>
    <origin rpy="0 0 0" xyz="0.052608 -0.015208 -0.010316"/>
    <geometry>
      <mesh filename="package://deep_ballbot_description/meshes/wheel_roller1_5_1.stl" scale="0.001 0.001 0.001"/>
    </geometry>
    <material name="silver"/>
  </visual>
  <collision>
    <origin rpy="0 0 0" xyz="0.052608 -0.015208 -0.010316"/>
    <geometry>
      <mesh filename="package://deep_ballbot_description/meshes/wheel_roller1_5_1.stl" scale="0.001 0.001 0.001"/>
    </geometry>
  </collision>
</link>

<link name="wheel_roller1_10_1">
  <inertial>
    <origin rpy="0 0 0" xyz="3.5748547960040566e-07 -3.6339927911993586e-07 9.819223642515418e-08"/>
    <mass value="0.001201137707108164"/>
    <inertia ixx="0.0" ixy="-0.0" ixz="-0.0" iyy="0.0" iyz="0.0" izz="0.0"/>
  </inertial>
  <visual>
    <origin rpy="0 0 0" xyz="0.041588 -0.024011 -0.005174"/>
    <geometry>
      <mesh filename="package://deep_ballbot_description/meshes/wheel_roller1_10_1.stl" scale="0.001 0.001 0.001"/>
    </geometry>
    <material name="silver"/>
  </visual>
  <collision>
    <origin rpy="0 0 0" xyz="0.041588 -0.024011 -0.005174"/>
    <geometry>
      <mesh filename="package://deep_ballbot_description/meshes/wheel_roller1_10_1.stl" scale="0.001 0.001 0.001"/>
    </geometry>
  </collision>
</link>

<link name="wheel_roller1_6_1">
  <inertial>
    <origin rpy="0 0 0" xyz="-1.5083097650026023e-07 4.3352494341619696e-07 -4.7480970870664163e-07"/>
    <mass value="0.0025623256301060132"/>
    <inertia ixx="0.0" ixy="0.0" ixz="0.0" iyy="0.0" iyz="0.0" izz="0.0"/>
  </inertial>
  <visual>
    <origin rpy="0 0 0" xyz="0.039475 -0.037946 -0.010313"/>
    <geometry>
      <mesh filename="package://deep_ballbot_description/meshes/wheel_roller1_6_1.stl" scale="0.001 0.001 0.001"/>
    </geometry>
    <material name="silver"/>
  </visual>
  <collision>
    <origin rpy="0 0 0" xyz="0.039475 -0.037946 -0.010313"/>
    <geometry>
      <mesh filename="package://deep_ballbot_description/meshes/wheel_roller1_6_1.stl" scale="0.001 0.001 0.001"/>
    </geometry>
  </collision>
</link>

<link name="wheel_roller1_11_1">
  <inertial>
    <origin rpy="0 0 0" xyz="1.520067159574423e-07 -6.254028831614855e-08 -3.0009008900044876e-07"/>
    <mass value="0.001201137707108158"/>
    <inertia ixx="0.0" ixy="0.0" ixz="0.0" iyy="0.0" iyz="-0.0" izz="0.0"/>
  </inertial>
  <visual>
    <origin rpy="0 0 0" xyz="0.037783 -0.051814 -0.015781"/>
    <geometry>
      <mesh filename="package://deep_ballbot_description/meshes/wheel_roller1_11_1.stl" scale="0.001 0.001 0.001"/>
    </geometry>
    <material name="silver"/>
  </visual>
  <collision>
    <origin rpy="0 0 0" xyz="0.037783 -0.051814 -0.015781"/>
    <geometry>
      <mesh filename="package://deep_ballbot_description/meshes/wheel_roller1_11_1.stl" scale="0.001 0.001 0.001"/>
    </geometry>
  </collision>
</link>

<link name="wheel_roller1_3_1">
  <inertial>
    <origin rpy="0 0 0" xyz="1.8441451420103672e-07 4.051678661673441e-07 3.016277917225474e-07"/>
    <mass value="0.0025623256301059937"/>
    <inertia ixx="0.0" ixy="-0.0" ixz="-0.0" iyy="0.0" iyz="0.0" izz="0.0"/>
  </inertial>
  <visual>
    <origin rpy="0 0 0" xyz="0.046834 -0.05735 -0.026387"/>
    <geometry>
      <mesh filename="package://deep_ballbot_description/meshes/wheel_roller1_3_1.stl" scale="0.001 0.001 0.001"/>
    </geometry>
    <material name="silver"/>
  </visual>
  <collision>
    <origin rpy="0 0 0" xyz="0.046834 -0.05735 -0.026387"/>
    <geometry>
      <mesh filename="package://deep_ballbot_description/meshes/wheel_roller1_3_1.stl" scale="0.001 0.001 0.001"/>
    </geometry>
  </collision>
</link>

<link name="wheel_roller1_8_1">
  <inertial>
    <origin rpy="0 0 0" xyz="-2.106407843288638e-08 -4.6082251350942904e-07 -9.665432527949935e-08"/>
    <mass value="0.0012011377071081484"/>
    <inertia ixx="0.0" ixy="-0.0" ixz="0.0" iyy="0.0" iyz="0.0" izz="0.0"/>
  </inertial>
  <visual>
    <origin rpy="0 0 0" xyz="0.056154 -0.062421 -0.036994"/>
    <geometry>
      <mesh filename="package://deep_ballbot_description/meshes/wheel_roller1_8_1.stl" scale="0.001 0.001 0.001"/>
    </geometry>
    <material name="silver"/>
  </visual>
  <collision>
    <origin rpy="0 0 0" xyz="0.056154 -0.062421 -0.036994"/>
    <geometry>
      <mesh filename="package://deep_ballbot_description/meshes/wheel_roller1_8_1.stl" scale="0.001 0.001 0.001"/>
    </geometry>
  </collision>
</link>

<link name="wheel_roller1_1_1">
  <inertial>
    <origin rpy="0 0 0" xyz="-4.803400587283235e-07 2.0996169466241943e-07 7.806477036326198e-08"/>
    <mass value="0.0025623256301060197"/>
    <inertia ixx="0.0" ixy="0.0" ixz="-0.0" iyy="0.0" iyz="-0.0" izz="0.0"/>
  </inertial>
  <visual>
    <origin rpy="0 0 0" xyz="0.067317 -0.054021 -0.042462"/>
    <geometry>
      <mesh filename="package://deep_ballbot_description/meshes/wheel_roller1_1_1.stl" scale="0.001 0.001 0.001"/>
    </geometry>
    <material name="silver"/>
  </visual>
  <collision>
    <origin rpy="0 0 0" xyz="0.067317 -0.054021 -0.042462"/>
    <geometry>
      <mesh filename="package://deep_ballbot_description/meshes/wheel_roller1_1_1.stl" scale="0.001 0.001 0.001"/>
    </geometry>
  </collision>
</link>

<link name="wheel_roller2_2_1">
  <inertial>
    <origin rpy="0 0 0" xyz="5.707539414713796e-17 3.1992732602015295e-07 -4.949365299475317e-07"/>
    <mass value="0.001201137707108136"/>
    <inertia ixx="0.0" ixy="-0.0" ixz="0.0" iyy="0.0" iyz="-0.0" izz="0.0"/>
  </inertial>
  <visual>
    <origin rpy="0 0 0" xyz="-0.0 0.090448 -0.047601"/>
    <geometry>
      <mesh filename="package://deep_ballbot_description/meshes/wheel_roller2_2_1.stl" scale="0.001 0.001 0.001"/>
    </geometry>
    <material name="silver"/>
  </visual>
  <collision>
    <origin rpy="0 0 0" xyz="-0.0 0.090448 -0.047601"/>
    <geometry>
      <mesh filename="package://deep_ballbot_description/meshes/wheel_roller2_2_1.stl" scale="0.001 0.001 0.001"/>
    </geometry>
  </collision>
</link>

<link name="wheel_roller2_4_1">
  <inertial>
    <origin rpy="0 0 0" xyz="0.0012986987297727952 0.0015200692565428692 0.09545975573465439"/>
    <mass value="0.002562325630105998"/>
    <inertia ixx="0.0" ixy="0.0" ixz="-0.0" iyy="0.0" iyz="-0.0" izz="0.0"/>
  </inertial>
  <visual>
    <origin rpy="0 0 0" xyz="-0.011783 0.086847 0.05298"/>
    <geometry>
      <mesh filename="package://deep_ballbot_description/meshes/wheel_roller2_4_1.stl" scale="0.001 0.001 0.001"/>
    </geometry>
    <material name="silver"/>
  </visual>
  <collision>
    <origin rpy="0 0 0" xyz="-0.011783 0.086847 0.05298"/>
    <geometry>
      <mesh filename="package://deep_ballbot_description/meshes/wheel_roller2_4_1.stl" scale="0.001 0.001 0.001"/>
    </geometry>
  </collision>
</link>

<link name="wheel_roller2_7_1">
  <inertial>
    <origin rpy="0 0 0" xyz="-2.3788655216863686e-07 -7.835488144425362e-08 -9.665444470480233e-08"/>
    <mass value="0.0012011377071081708"/>
    <inertia ixx="0.0" ixy="-0.0" ixz="0.0" iyy="0.0" iyz="0.0" izz="0.0"/>
  </inertial>
  <visual>
    <origin rpy="0 0 0" xyz="-0.025981 0.079841 -0.036994"/>
    <geometry>
      <mesh filename="package://deep_ballbot_description/meshes/wheel_roller2_7_1.stl" scale="0.001 0.001 0.001"/>
    </geometry>
    <material name="silver"/>
  </visual>
  <collision>
    <origin rpy="0 0 0" xyz="-0.025981 0.079841 -0.036994"/>
    <geometry>
      <mesh filename="package://deep_ballbot_description/meshes/wheel_roller2_7_1.stl" scale="0.001 0.001 0.001"/>
    </geometry>
  </collision>
</link>

<link name="wheel_roller2_12_1">
  <inertial>
    <origin rpy="0 0 0" xyz="-4.104702688856321e-14 -4.7663711762180316e-07 3.016277912958054e-07"/>
    <mass value="0.002562325630106007"/>
    <inertia ixx="0.0" ixy="0.0" ixz="0.0" iyy="0.0" iyz="-0.0" izz="0.0"/>
  </inertial>
  <visual>
    <origin rpy="0 0 0" xyz="-0.02625 0.069234 -0.026387"/>
    <geometry>
      <mesh filename="package://deep_ballbot_description/meshes/wheel_roller2_12_1.stl" scale="0.001 0.001 0.001"/>
    </geometry>
    <material name="silver"/>
  </visual>
  <collision>
    <origin rpy="0 0 0" xyz="-0.02625 0.069234 -0.026387"/>
    <geometry>
      <mesh filename="package://deep_ballbot_description/meshes/wheel_roller2_12_1.stl" scale="0.001 0.001 0.001"/>
    </geometry>
  </collision>
</link>

<link name="wheel_roller2_9_1">
  <inertial>
    <origin rpy="0 0 0" xyz="-2.3788655466316921e-07 1.3562874434658312e-09 -1.7636561404701934e-07"/>
    <mass value="0.0012011377071081688"/>
    <inertia ixx="0.0" ixy="0.0" ixz="-0.0" iyy="0.0" iyz="0.0" izz="0.0"/>
  </inertial>
  <visual>
    <origin rpy="0 0 0" xyz="-0.025986 0.058634 -0.015787"/>
    <geometry>
      <mesh filename="package://deep_ballbot_description/meshes/wheel_roller2_9_1.stl" scale="0.001 0.001 0.001"/>
    </geometry>
    <material name="silver"/>
  </visual>
  <collision>
    <origin rpy="0 0 0" xyz="-0.025986 0.058634 -0.015787"/>
    <geometry>
      <mesh filename="package://deep_ballbot_description/meshes/wheel_roller2_9_1.stl" scale="0.001 0.001 0.001"/>
    </geometry>
  </collision>
</link>

<link name="wheel_roller2_5_1">
  <inertial>
    <origin rpy="0 0 0" xyz="-3.3974599705603736e-07 -2.3573421612660406e-07 6.072436550992599e-08"/>
    <mass value="0.0025623256301060093"/>
    <inertia ixx="0.0" ixy="-0.0" ixz="0.0" iyy="0.0" iyz="-0.0" izz="0.0"/>
  </inertial>
  <visual>
    <origin rpy="0 0 0" xyz="-0.013134 0.053163 -0.010316"/>
    <geometry>
      <mesh filename="package://deep_ballbot_description/meshes/wheel_roller2_5_1.stl" scale="0.001 0.001 0.001"/>
    </geometry>
    <material name="silver"/>
  </visual>
  <collision>
    <origin rpy="0 0 0" xyz="-0.013134 0.053163 -0.010316"/>
    <geometry>
      <mesh filename="package://deep_ballbot_description/meshes/wheel_roller2_5_1.stl" scale="0.001 0.001 0.001"/>
    </geometry>
  </collision>
</link>

<link name="wheel_roller2_10_1">
  <inertial>
    <origin rpy="0 0 0" xyz="8.256644157150852e-17 -2.732015629489104e-07 9.81921130394775e-08"/>
    <mass value="0.0012011377071081241"/>
    <inertia ixx="0.0" ixy="0.0" ixz="-0.0" iyy="0.0" iyz="-0.0" izz="0.0"/>
  </inertial>
  <visual>
    <origin rpy="0 0 0" xyz="-0.0 0.048021 -0.005174"/>
    <geometry>
      <mesh filename="package://deep_ballbot_description/meshes/wheel_roller2_10_1.stl" scale="0.001 0.001 0.001"/>
    </geometry>
    <material name="silver"/>
  </visual>
  <collision>
    <origin rpy="0 0 0" xyz="-0.0 0.048021 -0.005174"/>
    <geometry>
      <mesh filename="package://deep_ballbot_description/meshes/wheel_roller2_10_1.stl" scale="0.001 0.001 0.001"/>
    </geometry>
  </collision>
</link>

<link name="wheel_roller2_6_1">
  <inertial>
    <origin rpy="0 0 0" xyz="3.71959407718947e-14 2.997996893655541e-07 -4.7480954020080735e-07"/>
    <mass value="0.002562325630106006"/>
    <inertia ixx="0.0" ixy="0.0" ixz="-0.0" iyy="0.0" iyz="-0.0" izz="0.0"/>
  </inertial>
  <visual>
    <origin rpy="0 0 0" xyz="0.013125 0.05316 -0.010313"/>
    <geometry>
      <mesh filename="package://deep_ballbot_description/meshes/wheel_roller2_6_1.stl" scale="0.001 0.001 0.001"/>
    </geometry>
    <material name="silver"/>
  </visual>
  <collision>
    <origin rpy="0 0 0" xyz="0.013125 0.05316 -0.010313"/>
    <geometry>
      <mesh filename="package://deep_ballbot_description/meshes/wheel_roller2_6_1.stl" scale="0.001 0.001 0.001"/>
    </geometry>
  </collision>
</link>

<link name="wheel_roller2_11_1">
  <inertial>
    <origin rpy="0 0 0" xyz="2.3788655228659805e-07 1.2508064507754657e-07 -3.0008997176089736e-07"/>
    <mass value="0.0012011377071081777"/>
    <inertia ixx="0.0" ixy="-0.0" ixz="0.0" iyy="0.0" iyz="0.0" izz="0.0"/>
  </inertial>
  <visual>
    <origin rpy="0 0 0" xyz="0.025981 0.058628 -0.015781"/>
    <geometry>
      <mesh filename="package://deep_ballbot_description/meshes/wheel_roller2_11_1.stl" scale="0.001 0.001 0.001"/>
    </geometry>
    <material name="silver"/>
  </visual>
  <collision>
    <origin rpy="0 0 0" xyz="0.025981 0.058628 -0.015781"/>
    <geometry>
      <mesh filename="package://deep_ballbot_description/meshes/wheel_roller2_11_1.stl" scale="0.001 0.001 0.001"/>
    </geometry>
  </collision>
</link>

<link name="wheel_roller2_3_1">
  <inertial>
    <origin rpy="0 0 0" xyz="4.1234377023968705e-14 -4.766371192593821e-07 3.016277919688781e-07"/>
    <mass value="0.0025623256301060154"/>
    <inertia ixx="0.0" ixy="-0.0" ixz="0.0" iyy="0.0" iyz="-0.0" izz="0.0"/>
  </inertial>
  <visual>
    <origin rpy="0 0 0" xyz="0.02625 0.069234 -0.026387"/>
    <geometry>
      <mesh filename="package://deep_ballbot_description/meshes/wheel_roller2_3_1.stl" scale="0.001 0.001 0.001"/>
    </geometry>
    <material name="silver"/>
  </visual>
  <collision>
    <origin rpy="0 0 0" xyz="0.02625 0.069234 -0.026387"/>
    <geometry>
      <mesh filename="package://deep_ballbot_description/meshes/wheel_roller2_3_1.stl" scale="0.001 0.001 0.001"/>
    </geometry>
  </collision>
</link>

<link name="wheel_roller2_8_1">
  <inertial>
    <origin rpy="0 0 0" xyz="2.3788655470480258e-07 -7.835488080587538e-08 -9.66544453084861e-08"/>
    <mass value="0.0012011377071081413"/>
    <inertia ixx="0.0" ixy="0.0" ixz="-0.0" iyy="0.0" iyz="0.0" izz="0.0"/>
  </inertial>
  <visual>
    <origin rpy="0 0 0" xyz="0.025981 0.079841 -0.036994"/>
    <geometry>
      <mesh filename="package://deep_ballbot_description/meshes/wheel_roller2_8_1.stl" scale="0.001 0.001 0.001"/>
    </geometry>
    <material name="silver"/>
  </visual>
  <collision>
    <origin rpy="0 0 0" xyz="0.025981 0.079841 -0.036994"/>
    <geometry>
      <mesh filename="package://deep_ballbot_description/meshes/wheel_roller2_8_1.stl" scale="0.001 0.001 0.001"/>
    </geometry>
  </collision>
</link>

<link name="wheel_roller2_1_1">
  <inertial>
    <origin rpy="0 0 0" xyz="3.7561967425325804e-14 -2.5307392746698465e-07 7.806512437175117e-08"/>
    <mass value="0.002562325630106022"/>
    <inertia ixx="0.0" ixy="-0.0" ixz="0.0" iyy="0.0" iyz="-0.0" izz="0.0"/>
  </inertial>
  <visual>
    <origin rpy="0 0 0" xyz="0.013125 0.085309 -0.042462"/>
    <geometry>
      <mesh filename="package://deep_ballbot_description/meshes/wheel_roller2_1_1.stl" scale="0.001 0.001 0.001"/>
    </geometry>
    <material name="silver"/>
  </visual>
  <collision>
    <origin rpy="0 0 0" xyz="0.013125 0.085309 -0.042462"/>
    <geometry>
      <mesh filename="package://deep_ballbot_description/meshes/wheel_roller2_1_1.stl" scale="0.001 0.001 0.001"/>
    </geometry>
  </collision>
</link>

<link name="wheel_roller3_2_1">
  <inertial>
    <origin rpy="0 0 0" xyz="-1.1343589803591847e-08 -1.599636009347316e-07 -4.949366527104426e-07"/>
    <mass value="0.0012011377071081653"/>
    <inertia ixx="0.0" ixy="0.0" ixz="-0.0" iyy="0.0" iyz="-0.0" izz="0.0"/>
  </inertial>
  <visual>
    <origin rpy="0 0 0" xyz="-0.07833 -0.045224 -0.047601"/>
    <geometry>
      <mesh filename="package://deep_ballbot_description/meshes/wheel_roller3_2_1.stl" scale="0.001 0.001 0.001"/>
    </geometry>
    <material name="silver"/>
  </visual>
  <collision>
    <origin rpy="0 0 0" xyz="-0.07833 -0.045224 -0.047601"/>
    <geometry>
      <mesh filename="package://deep_ballbot_description/meshes/wheel_roller3_2_1.stl" scale="0.001 0.001 0.001"/>
    </geometry>
  </collision>
</link>

<link name="wheel_roller3_4_1">
  <inertial>
    <origin rpy="0 0 0" xyz="-0.0019665597139539304 0.00036454879645892585 0.09545975573430025"/>
    <mass value="0.0025623256301060137"/>
    <inertia ixx="0.0" ixy="-0.0" ixz="0.0" iyy="0.0" iyz="-0.0" izz="0.0"/>
  </inertial>
  <visual>
    <origin rpy="0 0 0" xyz="-0.069321 -0.053628 0.05298"/>
    <geometry>
      <mesh filename="package://deep_ballbot_description/meshes/wheel_roller3_4_1.stl" scale="0.001 0.001 0.001"/>
    </geometry>
    <material name="silver"/>
  </visual>
  <collision>
    <origin rpy="0 0 0" xyz="-0.069321 -0.053628 0.05298"/>
    <geometry>
      <mesh filename="package://deep_ballbot_description/meshes/wheel_roller3_4_1.stl" scale="0.001 0.001 0.001"/>
    </geometry>
  </collision>
</link>

<link name="wheel_roller3_9_1">
  <inertial>
    <origin rpy="0 0 0" xyz="2.1064078051247215e-08 -4.60822511420822e-07 -9.6654324321932e-08"/>
    <mass value="0.0012011377071081484"/>
    <inertia ixx="0.0" ixy="0.0" ixz="-0.0" iyy="0.0" iyz="0.0" izz="0.0"/>
  </inertial>
  <visual>
    <origin rpy="0 0 0" xyz="-0.056154 -0.062421 -0.036994"/>
    <geometry>
      <mesh filename="package://deep_ballbot_description/meshes/wheel_roller3_9_1.stl" scale="0.001 0.001 0.001"/>
    </geometry>
    <material name="silver"/>
  </visual>
  <collision>
    <origin rpy="0 0 0" xyz="-0.056154 -0.062421 -0.036994"/>
    <geometry>
      <mesh filename="package://deep_ballbot_description/meshes/wheel_roller3_9_1.stl" scale="0.001 0.001 0.001"/>
    </geometry>
  </collision>
</link>

<link name="wheel_roller3_7_1">
  <inertial>
    <origin rpy="0 0 0" xyz="-1.8441451390266428e-07 4.051678657579494e-07 3.0162779186132527e-07"/>
    <mass value="0.002562325630105985"/>
    <inertia ixx="0.0" ixy="0.0" ixz="0.0" iyy="0.0" iyz="0.0" izz="0.0"/>
  </inertial>
  <visual>
    <origin rpy="0 0 0" xyz="-0.046834 -0.05735 -0.026387"/>
    <geometry>
      <mesh filename="package://deep_ballbot_description/meshes/wheel_roller3_7_1.stl" scale="0.001 0.001 0.001"/>
    </geometry>
    <material name="silver"/>
  </visual>
  <collision>
    <origin rpy="0 0 0" xyz="-0.046834 -0.05735 -0.026387"/>
    <geometry>
      <mesh filename="package://deep_ballbot_description/meshes/wheel_roller3_7_1.stl" scale="0.001 0.001 0.001"/>
    </geometry>
  </collision>
</link>

<link name="wheel_roller3_12_1">
  <inertial>
    <origin rpy="0 0 0" xyz="-3.487058552881228e-07 3.2944890811931193e-07 -1.7636573078697038e-07"/>
    <mass value="0.001201137707108146"/>
    <inertia ixx="0.0" ixy="-0.0" ixz="-0.0" iyy="0.0" iyz="-0.0" izz="0.0"/>
  </inertial>
  <visual>
    <origin rpy="0 0 0" xyz="-0.037786 -0.051821 -0.015787"/>
    <geometry>
      <mesh filename="package://deep_ballbot_description/meshes/wheel_roller3_12_1.stl" scale="0.001 0.001 0.001"/>
    </geometry>
    <material name="silver"/>
  </visual>
  <collision>
    <origin rpy="0 0 0" xyz="-0.037786 -0.051821 -0.015787"/>
    <geometry>
      <mesh filename="package://deep_ballbot_description/meshes/wheel_roller3_12_1.stl" scale="0.001 0.001 0.001"/>
    </geometry>
  </collision>
</link>

<link name="wheel_roller3_5_1">
  <inertial>
    <origin rpy="0 0 0" xyz="-1.174338652848439e-07 -2.9870810204501996e-07 6.072419652530803e-08"/>
    <mass value="0.0025623256301059998"/>
    <inertia ixx="0.0" ixy="-0.0" ixz="-0.0" iyy="0.0" iyz="0.0" izz="0.0"/>
  </inertial>
  <visual>
    <origin rpy="0 0 0" xyz="-0.039474 -0.037956 -0.010316"/>
    <geometry>
      <mesh filename="package://deep_ballbot_description/meshes/wheel_roller3_5_1.stl" scale="0.001 0.001 0.001"/>
    </geometry>
    <material name="silver"/>
  </visual>
  <collision>
    <origin rpy="0 0 0" xyz="-0.039474 -0.037956 -0.010316"/>
    <geometry>
      <mesh filename="package://deep_ballbot_description/meshes/wheel_roller3_5_1.stl" scale="0.001 0.001 0.001"/>
    </geometry>
  </collision>
</link>

<link name="wheel_roller3_10_1">
  <inertial>
    <origin rpy="0 0 0" xyz="-3.5748547948938336e-07 -3.6339927917197756e-07 9.819223660296333e-08"/>
    <mass value="0.0012011377071081497"/>
    <inertia ixx="0.0" ixy="0.0" ixz="0.0" iyy="0.0" iyz="0.0" izz="0.0"/>
  </inertial>
  <visual>
    <origin rpy="0 0 0" xyz="-0.041588 -0.024011 -0.005174"/>
    <geometry>
      <mesh filename="package://deep_ballbot_description/meshes/wheel_roller3_10_1.stl" scale="0.001 0.001 0.001"/>
    </geometry>
    <material name="silver"/>
  </visual>
  <collision>
    <origin rpy="0 0 0" xyz="-0.041588 -0.024011 -0.005174"/>
    <geometry>
      <mesh filename="package://deep_ballbot_description/meshes/wheel_roller3_10_1.stl" scale="0.001 0.001 0.001"/>
    </geometry>
  </collision>
</link>

<link name="wheel_roller3_6_1">
  <inertial>
    <origin rpy="0 0 0" xyz="1.5083087315931332e-07 2.6667542579045245e-07 -4.7480918546199957e-07"/>
    <mass value="0.002562325630105979"/>
    <inertia ixx="0.0" ixy="-0.0" ixz="0.0" iyy="0.0" iyz="-0.0" izz="0.0"/>
  </inertial>
  <visual>
    <origin rpy="0 0 0" xyz="-0.0526 -0.015213 -0.010313"/>
    <geometry>
      <mesh filename="package://deep_ballbot_description/meshes/wheel_roller3_6_1.stl" scale="0.001 0.001 0.001"/>
    </geometry>
    <material name="silver"/>
  </visual>
  <collision>
    <origin rpy="0 0 0" xyz="-0.0526 -0.015213 -0.010313"/>
    <geometry>
      <mesh filename="package://deep_ballbot_description/meshes/wheel_roller3_6_1.stl" scale="0.001 0.001 0.001"/>
    </geometry>
  </collision>
</link>

<link name="wheel_roller3_11_1">
  <inertial>
    <origin rpy="0 0 0" xyz="-3.8989314721238344e-07 -6.25403686312434e-08 -3.000900918766203e-07"/>
    <mass value="0.0012011377071081616"/>
    <inertia ixx="0.0" ixy="0.0" ixz="-0.0" iyy="0.0" iyz="0.0" izz="0.0"/>
  </inertial>
  <visual>
    <origin rpy="0 0 0" xyz="-0.063764 -0.006814 -0.015781"/>
    <geometry>
      <mesh filename="package://deep_ballbot_description/meshes/wheel_roller3_11_1.stl" scale="0.001 0.001 0.001"/>
    </geometry>
    <material name="silver"/>
  </visual>
  <collision>
    <origin rpy="0 0 0" xyz="-0.063764 -0.006814 -0.015781"/>
    <geometry>
      <mesh filename="package://deep_ballbot_description/meshes/wheel_roller3_11_1.stl" scale="0.001 0.001 0.001"/>
    </geometry>
  </collision>
</link>

<link name="wheel_roller3_3_1">
  <inertial>
    <origin rpy="0 0 0" xyz="-1.844145546409104e-07 7.146925429073192e-08 3.0162779237827286e-07"/>
    <mass value="0.002562325630105982"/>
    <inertia ixx="0.0" ixy="0.0" ixz="0.0" iyy="0.0" iyz="0.0" izz="0.0"/>
  </inertial>
  <visual>
    <origin rpy="0 0 0" xyz="-0.073084 -0.011884 -0.026387"/>
    <geometry>
      <mesh filename="package://deep_ballbot_description/meshes/wheel_roller3_3_1.stl" scale="0.001 0.001 0.001"/>
    </geometry>
    <material name="silver"/>
  </visual>
  <collision>
    <origin rpy="0 0 0" xyz="-0.073084 -0.011884 -0.026387"/>
    <geometry>
      <mesh filename="package://deep_ballbot_description/meshes/wheel_roller3_3_1.stl" scale="0.001 0.001 0.001"/>
    </geometry>
  </collision>
</link>

<link name="wheel_roller3_8_1">
  <inertial>
    <origin rpy="0 0 0" xyz="-2.1682235507025638e-07 -4.608225904131902e-07 -9.665432838812382e-08"/>
    <mass value="0.0012011377071081688"/>
    <inertia ixx="0.0" ixy="-0.0" ixz="-0.0" iyy="0.0" iyz="-0.0" izz="0.0"/>
  </inertial>
  <visual>
    <origin rpy="0 0 0" xyz="-0.082135 -0.017421 -0.036994"/>
    <geometry>
      <mesh filename="package://deep_ballbot_description/meshes/wheel_roller3_8_1.stl" scale="0.001 0.001 0.001"/>
    </geometry>
    <material name="silver"/>
  </visual>
  <collision>
    <origin rpy="0 0 0" xyz="-0.082135 -0.017421 -0.036994"/>
    <geometry>
      <mesh filename="package://deep_ballbot_description/meshes/wheel_roller3_8_1.stl" scale="0.001 0.001 0.001"/>
    </geometry>
  </collision>
</link>

<link name="wheel_roller3_1_1">
  <inertial>
    <origin rpy="0 0 0" xyz="4.803399548114484e-07 4.311217745300855e-08 7.806529331993994e-08"/>
    <mass value="0.002562325630106003"/>
    <inertia ixx="0.0" ixy="-0.0" ixz="-0.0" iyy="0.0" iyz="0.0" izz="0.0"/>
  </inertial>
  <visual>
    <origin rpy="0 0 0" xyz="-0.080442 -0.031288 -0.042462"/>
    <geometry>
      <mesh filename="package://deep_ballbot_description/meshes/wheel_roller3_1_1.stl" scale="0.001 0.001 0.001"/>
    </geometry>
    <material name="silver"/>
  </visual>
  <collision>
    <origin rpy="0 0 0" xyz="-0.080442 -0.031288 -0.042462"/>
    <geometry>
      <mesh filename="package://deep_ballbot_description/meshes/wheel_roller3_1_1.stl" scale="0.001 0.001 0.001"/>
    </geometry>
  </collision>
</link>

<link name="simplefocshield1_1">
  <inertial>
    <origin rpy="0 0 0" xyz="0.004365878017930057 -0.038360427121610766 0.10845466263105585"/>
    <mass value="0.08735557008432586"/>
    <inertia ixx="4.9e-05" ixy="1.3e-05" ixz="-0.0" iyy="3e-05" iyz="2e-06" izz="3.4e-05"/>
  </inertial>
  <visual>
    <origin rpy="0 0 0" xyz="0.048464 -0.009499 -0.0149"/>
    <geometry>
      <mesh filename="package://deep_ballbot_description/meshes/simplefocshield1_1.stl" scale="0.001 0.001 0.001"/>
    </geometry>
    <material name="silver"/>
  </visual>
  <collision>
    <origin rpy="0 0 0" xyz="0.048464 -0.009499 -0.0149"/>
    <geometry>
      <mesh filename="package://deep_ballbot_description/meshes/simplefocshield1_1.stl" scale="0.001 0.001 0.001"/>
    </geometry>
  </collision>
</link>

<link name="simplefocshield2_1">
  <inertial>
    <origin rpy="0 0 0" xyz="0.0310377901406773 0.022960619393022408 0.10845466286207715"/>
    <mass value="0.08735557070138866"/>
    <inertia ixx="4.6e-05" ixy="-1.4e-05" ixz="-2e-06" iyy="3.3e-05" iyz="-1e-06" izz="3.4e-05"/>
  </inertial>
  <visual>
    <origin rpy="0 0 0" xyz="-0.016006 0.04672 -0.0149"/>
    <geometry>
      <mesh filename="package://deep_ballbot_description/meshes/simplefocshield2_1.stl" scale="0.001 0.001 0.001"/>
    </geometry>
    <material name="silver"/>
  </visual>
  <collision>
    <origin rpy="0 0 0" xyz="-0.016006 0.04672 -0.0149"/>
    <geometry>
      <mesh filename="package://deep_ballbot_description/meshes/simplefocshield2_1.stl" scale="0.001 0.001 0.001"/>
    </geometry>
  </collision>
</link>

<link name="simplefocshield3_1">
  <inertial>
    <origin rpy="0 0 0" xyz="-0.03540366842883193 0.015398807513328415 0.1084546626727809"/>
    <mass value="0.087355572863096"/>
    <inertia ixx="2.4e-05" ixy="2e-06" ixz="2e-06" iyy="5.5e-05" iyz="-1e-06" izz="3.4e-05"/>
  </inertial>
  <visual>
    <origin rpy="0 0 0" xyz="-0.032458 -0.037222 -0.0149"/>
    <geometry>
      <mesh filename="package://deep_ballbot_description/meshes/simplefocshield3_1.stl" scale="0.001 0.001 0.001"/>
    </geometry>
    <material name="silver"/>
  </visual>
  <collision>
    <origin rpy="0 0 0" xyz="-0.032458 -0.037222 -0.0149"/>
    <geometry>
      <mesh filename="package://deep_ballbot_description/meshes/simplefocshield3_1.stl" scale="0.001 0.001 0.001"/>
    </geometry>
  </collision>
</link>

<link name="base_plate1_1">
  <inertial>
    <origin rpy="0 0 0" xyz="0.02671557507531077 -0.005670206030588898 0.0029137797806522286"/>
    <mass value="0.029331775102842895"/>
    <inertia ixx="1.5e-05" ixy="6e-06" ixz="0.0" iyy="9e-06" iyz="0.0" izz="2.4e-05"/>
  </inertial>
  <visual>
    <origin rpy="0 0 0" xyz="0.059036 0.01299 -0.086"/>
    <geometry>
      <mesh filename="package://deep_ballbot_description/meshes/base_plate1_1.stl" scale="0.001 0.001 0.001"/>
    </geometry>
    <material name="silver"/>
  </visual>
  <collision>
    <origin rpy="0 0 0" xyz="0.059036 0.01299 -0.086"/>
    <geometry>
      <mesh filename="package://deep_ballbot_description/meshes/base_plate1_1.stl" scale="0.001 0.001 0.001"/>
    </geometry>
  </collision>
</link>

<link name="top_plate_1">
  <inertial>
    <origin rpy="0 0 0" xyz="0.023920999358290042 0.013810999483771355 0.00013943878334446436"/>
    <mass value="0.03865794031509113"/>
    <inertia ixx="2.6e-05" ixy="-0.0" ixz="-0.0" iyy="2.6e-05" iyz="-0.0" izz="5.2e-05"/>
  </inertial>
  <visual>
    <origin rpy="0 0 0" xyz="0.023921 0.013811 -0.157"/>
    <geometry>
      <mesh filename="package://deep_ballbot_description/meshes/top_plate_1.stl" scale="0.001 0.001 0.001"/>
    </geometry>
    <material name="silver"/>
  </visual>
  <collision>
    <origin rpy="0 0 0" xyz="0.023921 0.013811 -0.157"/>
    <geometry>
      <mesh filename="package://deep_ballbot_description/meshes/top_plate_1.stl" scale="0.001 0.001 0.001"/>
    </geometry>
  </collision>
</link>

<joint name="Rigid1" type="fixed">
  <origin rpy="0 0 0" xyz="0.0 0.0 0.041"/>
  <parent link="base_link"/>
  <child link="base_shell1_1"/>
</joint>

<joint name="Rigid2" type="fixed">
  <origin rpy="0 0 0" xyz="0.0 0.0 0.041"/>
  <parent link="base_link"/>
  <child link="base_shell2_1"/>
</joint>

<joint name="Rigid3" type="fixed">
  <origin rpy="0 0 0" xyz="0.0 0.0 0.041"/>
  <parent link="base_link"/>
  <child link="base_shell3_1"/>
</joint>

<joint name="Rigid5" type="fixed">
  <origin rpy="0 0 0" xyz="0.040768 -0.044631 0.045"/>
  <parent link="base_shell2_1"/>
  <child link="base_plate2_1"/>
</joint>

<joint name="Rigid6" type="fixed">
  <origin rpy="0 0 0" xyz="0.018268 0.057622 0.045"/>
  <parent link="base_shell3_1"/>
  <child link="base_plate3_1"/>
</joint>

<joint name="Rigid7" type="fixed">
  <origin rpy="0 0 0" xyz="0.035115 -0.000821 0.003"/>
  <parent link="base_plate1_1"/>
  <child link="vertical_bay1_1"/>
</joint>

<joint name="Rigid8" type="fixed">
  <origin rpy="0 0 0" xyz="-0.016847 0.03082 0.003"/>
  <parent link="base_plate2_1"/>
  <child link="vertical_bay2_1"/>
</joint>

<joint name="Rigid9" type="fixed">
  <origin rpy="0 0 0" xyz="-0.018268 -0.03 0.003"/>
  <parent link="base_plate3_1"/>
  <child link="vertical_bay3_1"/>
</joint>

<joint name="Rigid11" type="fixed">
  <origin rpy="0 0 0" xyz="0.023921 -0.03382 0.003"/>
  <parent link="top_plate_1"/>
  <child link="breadboard_1"/>
</joint>

<joint name="Rigid12" type="fixed">
  <origin rpy="0 0 0" xyz="0.000352 0.01596 0.095"/>
  <parent link="breadboard_1"/>
  <child link="arduino_nano_1"/>
</joint>

<joint name="Rigid13" type="fixed">
  <origin rpy="0 0 0" xyz="0.023921 0.024311 0.003"/>
  <parent link="top_plate_1"/>
  <child link="rasbperry_pi_1"/>
</joint>

<joint name="Rigid14" type="fixed">
  <origin rpy="0 0 0" xyz="-0.046487 0.026839 0.032056"/>
  <parent link="base_shell1_1"/>
  <child link="motor_mount1_1"/>
</joint>

<joint name="Rigid15" type="fixed">
  <origin rpy="0 0 0" xyz="0.0 -0.053678 0.032056"/>
  <parent link="base_shell2_1"/>
  <child link="motor_mount2_1"/>
</joint>

<joint name="Rigid16" type="fixed">
  <origin rpy="0 0 0" xyz="0.046487 0.026839 0.032056"/>
  <parent link="base_shell3_1"/>
  <child link="motor_mount3_1"/>
</joint>

<joint name="Rigid17" type="fixed">
  <origin rpy="0 0 0" xyz="-0.002598 -0.0015 0.0325"/>
  <parent link="vertical_bay1_1"/>
  <child link="arduino_mount1_1"/>
</joint>

<joint name="Rigid18" type="fixed">
  <origin rpy="0 0 0" xyz="0.002598 -0.0015 0.0325"/>
  <parent link="vertical_bay2_1"/>
  <child link="arduino_mount2_1"/>
</joint>

<joint name="Rigid19" type="fixed">
  <origin rpy="0 0 0" xyz="0.0 0.003 0.0325"/>
  <parent link="vertical_bay3_1"/>
  <child link="arduino_mount3_1"/>
</joint>

<joint name="Rigid20" type="fixed">
  <origin rpy="0 0 0" xyz="-0.020559 0.02561 -0.0085"/>
  <parent link="arduino_mount1_1"/>
  <child link="arduino1_1"/>
</joint>

<joint name="Rigid21" type="fixed">
  <origin rpy="0 0 0" xyz="-0.011899 -0.030609 -0.0085"/>
  <parent link="arduino_mount2_1"/>
  <child link="arduino2_1"/>
</joint>

<joint name="Rigid22" type="fixed">
  <origin rpy="0 0 0" xyz="0.032458 0.005 -0.0085"/>
  <parent link="arduino_mount3_1"/>
  <child link="arduino3_1"/>
</joint>

<joint name="Rigid23" type="fixed">
  <origin rpy="0 0 0" xyz="-0.004899 0.002828 -0.005657"/>
  <parent link="motor_mount1_1"/>
  <child link="motor_stator1_1"/>
</joint>

<joint name="Rigid24" type="fixed">
  <origin rpy="0 0 0" xyz="0.0 -0.005657 -0.005657"/>
  <parent link="motor_mount2_1"/>
  <child link="motor_stator2_1"/>
</joint>

<joint name="Rigid25" type="fixed">
  <origin rpy="0 0 0" xyz="0.004899 0.002828 -0.005657"/>
  <parent link="motor_mount3_1"/>
  <child link="motor_stator3_1"/>
</joint>

<joint name="MotorJoint1" type="continuous">
  <origin rpy="0 0 0" xyz="0.009798 -0.005656 -0.114798"/>
  <parent link="motor_stator1_1"/>
  <child link="motor_rotor1_1"/>
  <axis xyz="-0.612372 0.353553 -0.707107"/>
</joint>

<joint name="MotorJoint2" type="continuous">
  <origin rpy="0 0 0" xyz="0.0 0.011314 -0.114798"/>
  <parent link="motor_stator2_1"/>
  <child link="motor_rotor2_1"/>
  <axis xyz="0.0 -0.707107 -0.707107"/>
</joint>

<joint name="MotorJoint3" type="continuous">
  <origin rpy="0 0 0" xyz="-0.009798 -0.005656 -0.114798"/>
  <parent link="motor_stator3_1"/>
  <child link="motor_rotor3_1"/>
  <axis xyz="0.612372 0.353553 -0.707107"/>
</joint>

<joint name="Rigid26" type="fixed">
  <origin rpy="0 0 0" xyz="-0.011267 0.006505 -0.013011"/>
  <parent link="motor_rotor1_1"/>
  <child link="wheel_body1_1"/>
</joint>

<joint name="Rigid27" type="fixed">
  <origin rpy="0 0 0" xyz="0.0 -0.013011 -0.013011"/>
  <parent link="motor_rotor2_1"/>
  <child link="wheel_body2_1"/>
</joint>

<joint name="Rigid28" type="fixed">
  <origin rpy="0 0 0" xyz="0.011267 0.006505 -0.013011"/>
  <parent link="motor_rotor3_1"/>
  <child link="wheel_body3_1"/>
</joint>

<joint name="Rev1" type="continuous">
  <origin rpy="0 0 0" xyz="-0.025475 0.014708 0.108011"/>
  <parent link="wheel_body1_1"/>
  <child link="wheel_roller1_2_1"/>
  <axis xyz="0.5 0.866025 0.0"/>
</joint>

<joint name="Rev2" type="continuous">
  <origin rpy="0 0 0" xyz="-0.028248 0.002704 0.00743"/>
  <parent link="wheel_body1_1"/>
  <child link="wheel_roller1_4_1"/>
  <axis xyz="-0.126826 -0.926777 -0.353553"/>
</joint>

<joint name="Rev3" type="continuous">
  <origin rpy="0 0 0" xyz="-0.02928 -0.013095 0.097404"/>
  <parent link="wheel_body1_1"/>
  <child link="wheel_roller1_9_1"/>
  <axis xyz="0.28033 -0.739199 -0.612372"/>
</joint>

<joint name="Rev4" type="continuous">
  <origin rpy="0 0 0" xyz="-0.020229 -0.018632 0.086797"/>
  <parent link="wheel_body1_1"/>
  <child link="wheel_roller1_7_1"/>
  <axis xyz="0.612372 -0.353553 -0.707107"/>
</joint>

<joint name="Rev5" type="continuous">
  <origin rpy="0 0 0" xyz="-0.010916 -0.023703 0.076197"/>
  <parent link="wheel_body1_1"/>
  <child link="wheel_roller1_12_1"/>
  <axis xyz="-0.78033 -0.126826 0.612372"/>
</joint>

<joint name="Rev6" type="continuous">
  <origin rpy="0 0 0" xyz="0.000247 -0.015308 0.070726"/>
  <parent link="wheel_body1_1"/>
  <child link="wheel_roller1_5_1"/>
  <axis xyz="0.739199 0.573223 -0.353553"/>
</joint>

<joint name="Rev7" type="continuous">
  <origin rpy="0 0 0" xyz="0.011267 -0.006505 0.065584"/>
  <parent link="wheel_body1_1"/>
  <child link="wheel_roller1_10_1"/>
  <axis xyz="-0.5 -0.866025 -0.0"/>
</joint>

<joint name="Rev8" type="continuous">
  <origin rpy="0 0 0" xyz="0.01338 0.00743 0.070723"/>
  <parent link="wheel_body1_1"/>
  <child link="wheel_roller1_6_1"/>
  <axis xyz="-0.126826 -0.926777 -0.353553"/>
</joint>

<joint name="Rev9" type="continuous">
  <origin rpy="0 0 0" xyz="0.015072 0.021298 0.076191"/>
  <parent link="wheel_body1_1"/>
  <child link="wheel_roller1_11_1"/>
  <axis xyz="0.28033 -0.739199 -0.612372"/>
</joint>

<joint name="Rev10" type="continuous">
  <origin rpy="0 0 0" xyz="0.006021 0.026834 0.086797"/>
  <parent link="wheel_body1_1"/>
  <child link="wheel_roller1_3_1"/>
  <axis xyz="0.612372 -0.353553 -0.707107"/>
</joint>

<joint name="Rev11" type="continuous">
  <origin rpy="0 0 0" xyz="-0.003299 0.031905 0.097404"/>
  <parent link="wheel_body1_1"/>
  <child link="wheel_roller1_8_1"/>
  <axis xyz="0.78033 0.126826 -0.612372"/>
</joint>

<joint name="Rev12" type="continuous">
  <origin rpy="0 0 0" xyz="-0.014462 0.023505 0.102872"/>
  <parent link="wheel_body1_1"/>
  <child link="wheel_roller1_1_1"/>
  <axis xyz="0.739199 0.573223 -0.353553"/>
</joint>

<joint name="Rev13" type="continuous">
  <origin rpy="0 0 0" xyz="0.0 -0.029416 0.108011"/>
  <parent link="wheel_body2_1"/>
  <child link="wheel_roller2_2_1"/>
  <axis xyz="-1.0 -0.0 -0.0"/>
</joint>

<joint name="Rev14" type="continuous">
  <origin rpy="0 0 0" xyz="0.011783 -0.025815 0.00743"/>
  <parent link="wheel_body2_1"/>
  <child link="wheel_roller2_4_1"/>
  <axis xyz="0.866025 0.353553 -0.353553"/>
</joint>

<joint name="Rev15" type="continuous">
  <origin rpy="0 0 0" xyz="0.025981 -0.018809 0.097404"/>
  <parent link="wheel_body2_1"/>
  <child link="wheel_roller2_7_1"/>
  <axis xyz="0.5 0.612372 -0.612372"/>
</joint>

<joint name="Rev16" type="continuous">
  <origin rpy="0 0 0" xyz="0.02625 -0.008202 0.086797"/>
  <parent link="wheel_body2_1"/>
  <child link="wheel_roller2_12_1"/>
  <axis xyz="0.0 0.707107 -0.707107"/>
</joint>

<joint name="Rev17" type="continuous">
  <origin rpy="0 0 0" xyz="0.025986 0.002398 0.076197"/>
  <parent link="wheel_body2_1"/>
  <child link="wheel_roller2_9_1"/>
  <axis xyz="0.5 -0.612372 0.612372"/>
</joint>

<joint name="Rev18" type="continuous">
  <origin rpy="0 0 0" xyz="0.013134 0.007869 0.070726"/>
  <parent link="wheel_body2_1"/>
  <child link="wheel_roller2_5_1"/>
  <axis xyz="-0.866025 0.353553 -0.353553"/>
</joint>

<joint name="Rev19" type="continuous">
  <origin rpy="0 0 0" xyz="0.0 0.013011 0.065584"/>
  <parent link="wheel_body2_1"/>
  <child link="wheel_roller2_10_1"/>
  <axis xyz="1.0 -0.0 -0.0"/>
</joint>

<joint name="Rev20" type="continuous">
  <origin rpy="0 0 0" xyz="-0.013125 0.007872 0.070723"/>
  <parent link="wheel_body2_1"/>
  <child link="wheel_roller2_6_1"/>
  <axis xyz="0.866025 0.353553 -0.353553"/>
</joint>

<joint name="Rev21" type="continuous">
  <origin rpy="0 0 0" xyz="-0.025981 0.002404 0.076191"/>
  <parent link="wheel_body2_1"/>
  <child link="wheel_roller2_11_1"/>
  <axis xyz="0.5 0.612372 -0.612372"/>
</joint>

<joint name="Rev22" type="continuous">
  <origin rpy="0 0 0" xyz="-0.02625 -0.008202 0.086797"/>
  <parent link="wheel_body2_1"/>
  <child link="wheel_roller2_3_1"/>
  <axis xyz="0.0 0.707107 -0.707107"/>
</joint>

<joint name="Rev23" type="continuous">
  <origin rpy="0 0 0" xyz="-0.025981 -0.018809 0.097404"/>
  <parent link="wheel_body2_1"/>
  <child link="wheel_roller2_8_1"/>
  <axis xyz="-0.5 0.612372 -0.612372"/>
</joint>

<joint name="Rev24" type="continuous">
  <origin rpy="0 0 0" xyz="-0.013125 -0.024277 0.102872"/>
  <parent link="wheel_body2_1"/>
  <child link="wheel_roller2_1_1"/>
  <axis xyz="-0.866025 0.353553 -0.353553"/>
</joint>

<joint name="Rev25" type="continuous">
  <origin rpy="0 0 0" xyz="0.025475 0.014708 0.108011"/>
  <parent link="wheel_body3_1"/>
  <child link="wheel_roller3_2_1"/>
  <axis xyz="0.5 -0.866025 -0.0"/>
</joint>

<joint name="Rev26" type="continuous">
  <origin rpy="0 0 0" xyz="0.016466 0.023112 0.00743"/>
  <parent link="wheel_body3_1"/>
  <child link="wheel_roller3_4_1"/>
  <axis xyz="-0.739199 0.573223 -0.353553"/>
</joint>

<joint name="Rev27" type="continuous">
  <origin rpy="0 0 0" xyz="0.003299 0.031905 0.097404"/>
  <parent link="wheel_body3_1"/>
  <child link="wheel_roller3_9_1"/>
  <axis xyz="-0.78033 0.126826 -0.612372"/>
</joint>

<joint name="Rev28" type="continuous">
  <origin rpy="0 0 0" xyz="-0.006021 0.026834 0.086797"/>
  <parent link="wheel_body3_1"/>
  <child link="wheel_roller3_7_1"/>
  <axis xyz="-0.612372 -0.353553 -0.707107"/>
</joint>

<joint name="Rev29" type="continuous">
  <origin rpy="0 0 0" xyz="-0.015069 0.021305 0.076197"/>
  <parent link="wheel_body3_1"/>
  <child link="wheel_roller3_12_1"/>
  <axis xyz="0.28033 0.739199 0.612372"/>
</joint>

<joint name="Rev30" type="continuous">
  <origin rpy="0 0 0" xyz="-0.013381 0.00744 0.070726"/>
  <parent link="wheel_body3_1"/>
  <child link="wheel_roller3_5_1"/>
  <axis xyz="0.126826 -0.926777 -0.353553"/>
</joint>

<joint name="Rev31" type="continuous">
  <origin rpy="0 0 0" xyz="-0.011267 -0.006505 0.065584"/>
  <parent link="wheel_body3_1"/>
  <child link="wheel_roller3_10_1"/>
  <axis xyz="-0.5 0.866025 0.0"/>
</joint>

<joint name="Rev32" type="continuous">
  <origin rpy="0 0 0" xyz="-0.000255 -0.015303 0.070723"/>
  <parent link="wheel_body3_1"/>
  <child link="wheel_roller3_6_1"/>
  <axis xyz="-0.739199 0.573223 -0.353553"/>
</joint>

<joint name="Rev33" type="continuous">
  <origin rpy="0 0 0" xyz="0.010909 -0.023702 0.076191"/>
  <parent link="wheel_body3_1"/>
  <child link="wheel_roller3_11_1"/>
  <axis xyz="-0.78033 0.126826 -0.612372"/>
</joint>

<joint name="Rev34" type="continuous">
  <origin rpy="0 0 0" xyz="0.020229 -0.018632 0.086797"/>
  <parent link="wheel_body3_1"/>
  <child link="wheel_roller3_3_1"/>
  <axis xyz="-0.612372 -0.353553 -0.707107"/>
</joint>

<joint name="Rev35" type="continuous">
  <origin rpy="0 0 0" xyz="0.02928 -0.013095 0.097404"/>
  <parent link="wheel_body3_1"/>
  <child link="wheel_roller3_8_1"/>
  <axis xyz="-0.28033 -0.739199 -0.612372"/>
</joint>

<joint name="Rev36" type="continuous">
  <origin rpy="0 0 0" xyz="0.027587 0.000772 0.102872"/>
  <parent link="wheel_body3_1"/>
  <child link="wheel_roller3_1_1"/>
  <axis xyz="0.126826 -0.926777 -0.353553"/>
</joint>

<joint name="Rigid29" type="fixed">
  <origin rpy="0 0 0" xyz="-0.001386 -0.0008 -0.0981"/>
  <parent link="arduino1_1"/>
  <child link="simplefocshield1_1"/>
</joint>

<joint name="Rigid30" type="fixed">
  <origin rpy="0 0 0" xyz="0.001386 -0.0008 -0.0981"/>
  <parent link="arduino2_1"/>
  <child link="simplefocshield2_1"/>
</joint>

<joint name="Rigid31" type="fixed">
  <origin rpy="0 0 0" xyz="0.0 0.0016 -0.0981"/>
  <parent link="arduino3_1"/>
  <child link="simplefocshield3_1"/>
</joint>

<joint name="Rigid4" type="fixed">
  <origin rpy="0 0 0" xyz="-0.059036 -0.01299 0.045"/>
  <parent link="base_shell1_1"/>
  <child link="base_plate1_1"/>
</joint>

<joint name="Rigid10" type="fixed">
  <origin rpy="0 0 0" xyz="0.0 0.0 0.068"/>
  <parent link="vertical_bay1_1"/>
  <child link="top_plate_1"/>
</joint>

</robot>
